{"message": "invalid literal for int() with base 10: '123456akhjgfjhgf'", "time": "2020-06-29T21:23:18.080893", "level": "DEBUG", "filename": "byte_conversion.py", "funcName": "byte_conversion_def", "module": "byte_conversion", "pathname": "/Users/jimburer/Git/cryptography/python_library/data/data_transformation/type_conversion/byte_conversion.py", "exc_info": "Traceback (most recent call last):\n  File \"/Users/jimburer/Git/cryptography/python_library/data/data_transformation/type_conversion/byte_conversion.py\", line 6, in byte_conversion_def\n    in_bytes_as_int = int(in_bytes)\nValueError: invalid literal for int() with base 10: '123456akhjgfjhgf'"}
{"message": "invalid literal for int() with base 10: '123456akhj'", "time": "2020-06-29T21:26:50.051270", "level": "DEBUG", "filename": "byte_conversion.py", "funcName": "byte_conversion_def", "module": "byte_conversion", "pathname": "/Users/jimburer/Git/cryptography/python_library/data/data_transformation/type_conversion/byte_conversion.py", "exc_info": "Traceback (most recent call last):\n  File \"/Users/jimburer/Git/cryptography/python_library/data/data_transformation/type_conversion/byte_conversion.py\", line 6, in byte_conversion_def\n    in_bytes_as_int = int(in_bytes)\nValueError: invalid literal for int() with base 10: '123456akhj'"}
{"message": "invalid literal for int() with base 10: 'test'", "time": "2020-06-30T17:34:44.267916", "level": "DEBUG", "filename": "byte_conversion.py", "funcName": "byte_conversion_def", "module": "byte_conversion", "pathname": "/Users/jimburer/Git/cryptography/python_library/data/data_transformation/type_conversion/byte_conversion.py", "exc_info": "Traceback (most recent call last):\n  File \"/Users/jimburer/Git/cryptography/python_library/data/data_transformation/type_conversion/byte_conversion.py\", line 6, in byte_conversion_def\n    in_bytes_as_int = int(in_bytes)\nValueError: invalid literal for int() with base 10: 'test'"}
{"message": "invalid literal for int() with base 10: 'test'", "time": "2020-06-30T17:34:44.418533", "level": "DEBUG", "filename": "byte_conversion.py", "funcName": "byte_conversion_def", "module": "byte_conversion", "pathname": "/Users/jimburer/Git/cryptography/python_library/data/data_transformation/type_conversion/byte_conversion.py", "exc_info": "Traceback (most recent call last):\n  File \"/Users/jimburer/Git/cryptography/python_library/data/data_transformation/type_conversion/byte_conversion.py\", line 6, in byte_conversion_def\n    in_bytes_as_int = int(in_bytes)\nValueError: invalid literal for int() with base 10: 'test'"}
{"message": "invalid literal for int() with base 10: 'test'", "time": "2020-06-30T17:34:48.072386", "level": "DEBUG", "filename": "byte_conversion.py", "funcName": "byte_conversion_def", "module": "byte_conversion", "pathname": "/Users/jimburer/Git/cryptography/python_library/data/data_transformation/type_conversion/byte_conversion.py", "exc_info": "Traceback (most recent call last):\n  File \"/Users/jimburer/Git/cryptography/python_library/data/data_transformation/type_conversion/byte_conversion.py\", line 6, in byte_conversion_def\n    in_bytes_as_int = int(in_bytes)\nValueError: invalid literal for int() with base 10: 'test'"}
{"message": "invalid literal for int() with base 10: 'test'", "time": "2020-06-30T17:34:48.556353", "level": "DEBUG", "filename": "byte_conversion.py", "funcName": "byte_conversion_def", "module": "byte_conversion", "pathname": "/Users/jimburer/Git/cryptography/python_library/data/data_transformation/type_conversion/byte_conversion.py", "exc_info": "Traceback (most recent call last):\n  File \"/Users/jimburer/Git/cryptography/python_library/data/data_transformation/type_conversion/byte_conversion.py\", line 6, in byte_conversion_def\n    in_bytes_as_int = int(in_bytes)\nValueError: invalid literal for int() with base 10: 'test'"}
{"message": "invalid literal for int() with base 10: 'test'", "time": "2020-06-30T17:34:48.838286", "level": "DEBUG", "filename": "byte_conversion.py", "funcName": "byte_conversion_def", "module": "byte_conversion", "pathname": "/Users/jimburer/Git/cryptography/python_library/data/data_transformation/type_conversion/byte_conversion.py", "exc_info": "Traceback (most recent call last):\n  File \"/Users/jimburer/Git/cryptography/python_library/data/data_transformation/type_conversion/byte_conversion.py\", line 6, in byte_conversion_def\n    in_bytes_as_int = int(in_bytes)\nValueError: invalid literal for int() with base 10: 'test'"}
{"message": "invalid literal for int() with base 10: 'test'", "time": "2020-06-30T17:34:48.985351", "level": "DEBUG", "filename": "byte_conversion.py", "funcName": "byte_conversion_def", "module": "byte_conversion", "pathname": "/Users/jimburer/Git/cryptography/python_library/data/data_transformation/type_conversion/byte_conversion.py", "exc_info": "Traceback (most recent call last):\n  File \"/Users/jimburer/Git/cryptography/python_library/data/data_transformation/type_conversion/byte_conversion.py\", line 6, in byte_conversion_def\n    in_bytes_as_int = int(in_bytes)\nValueError: invalid literal for int() with base 10: 'test'"}
{"message": "invalid literal for int() with base 10: 'test'", "time": "2020-06-30T17:34:49.142829", "level": "DEBUG", "filename": "byte_conversion.py", "funcName": "byte_conversion_def", "module": "byte_conversion", "pathname": "/Users/jimburer/Git/cryptography/python_library/data/data_transformation/type_conversion/byte_conversion.py", "exc_info": "Traceback (most recent call last):\n  File \"/Users/jimburer/Git/cryptography/python_library/data/data_transformation/type_conversion/byte_conversion.py\", line 6, in byte_conversion_def\n    in_bytes_as_int = int(in_bytes)\nValueError: invalid literal for int() with base 10: 'test'"}
{"message": "invalid literal for int() with base 10: 'test'", "time": "2020-06-30T17:34:49.282798", "level": "DEBUG", "filename": "byte_conversion.py", "funcName": "byte_conversion_def", "module": "byte_conversion", "pathname": "/Users/jimburer/Git/cryptography/python_library/data/data_transformation/type_conversion/byte_conversion.py", "exc_info": "Traceback (most recent call last):\n  File \"/Users/jimburer/Git/cryptography/python_library/data/data_transformation/type_conversion/byte_conversion.py\", line 6, in byte_conversion_def\n    in_bytes_as_int = int(in_bytes)\nValueError: invalid literal for int() with base 10: 'test'"}
{"message": "invalid literal for int() with base 10: 'test'", "time": "2020-06-30T17:34:49.410107", "level": "DEBUG", "filename": "byte_conversion.py", "funcName": "byte_conversion_def", "module": "byte_conversion", "pathname": "/Users/jimburer/Git/cryptography/python_library/data/data_transformation/type_conversion/byte_conversion.py", "exc_info": "Traceback (most recent call last):\n  File \"/Users/jimburer/Git/cryptography/python_library/data/data_transformation/type_conversion/byte_conversion.py\", line 6, in byte_conversion_def\n    in_bytes_as_int = int(in_bytes)\nValueError: invalid literal for int() with base 10: 'test'"}
{"message": "invalid literal for int() with base 10: 'test'", "time": "2020-06-30T17:34:49.542202", "level": "DEBUG", "filename": "byte_conversion.py", "funcName": "byte_conversion_def", "module": "byte_conversion", "pathname": "/Users/jimburer/Git/cryptography/python_library/data/data_transformation/type_conversion/byte_conversion.py", "exc_info": "Traceback (most recent call last):\n  File \"/Users/jimburer/Git/cryptography/python_library/data/data_transformation/type_conversion/byte_conversion.py\", line 6, in byte_conversion_def\n    in_bytes_as_int = int(in_bytes)\nValueError: invalid literal for int() with base 10: 'test'"}
{"message": "invalid literal for int() with base 10: 'test'", "time": "2020-06-30T17:34:49.661549", "level": "DEBUG", "filename": "byte_conversion.py", "funcName": "byte_conversion_def", "module": "byte_conversion", "pathname": "/Users/jimburer/Git/cryptography/python_library/data/data_transformation/type_conversion/byte_conversion.py", "exc_info": "Traceback (most recent call last):\n  File \"/Users/jimburer/Git/cryptography/python_library/data/data_transformation/type_conversion/byte_conversion.py\", line 6, in byte_conversion_def\n    in_bytes_as_int = int(in_bytes)\nValueError: invalid literal for int() with base 10: 'test'"}
{"message": "invalid literal for int() with base 10: 'test'", "time": "2020-06-30T17:34:49.831646", "level": "DEBUG", "filename": "byte_conversion.py", "funcName": "byte_conversion_def", "module": "byte_conversion", "pathname": "/Users/jimburer/Git/cryptography/python_library/data/data_transformation/type_conversion/byte_conversion.py", "exc_info": "Traceback (most recent call last):\n  File \"/Users/jimburer/Git/cryptography/python_library/data/data_transformation/type_conversion/byte_conversion.py\", line 6, in byte_conversion_def\n    in_bytes_as_int = int(in_bytes)\nValueError: invalid literal for int() with base 10: 'test'"}
{"message": "invalid literal for int() with base 10: 'test'", "time": "2020-06-30T17:34:49.985770", "level": "DEBUG", "filename": "byte_conversion.py", "funcName": "byte_conversion_def", "module": "byte_conversion", "pathname": "/Users/jimburer/Git/cryptography/python_library/data/data_transformation/type_conversion/byte_conversion.py", "exc_info": "Traceback (most recent call last):\n  File \"/Users/jimburer/Git/cryptography/python_library/data/data_transformation/type_conversion/byte_conversion.py\", line 6, in byte_conversion_def\n    in_bytes_as_int = int(in_bytes)\nValueError: invalid literal for int() with base 10: 'test'"}
{"message": "invalid literal for int() with base 10: 'test'", "time": "2020-06-30T17:34:50.131705", "level": "DEBUG", "filename": "byte_conversion.py", "funcName": "byte_conversion_def", "module": "byte_conversion", "pathname": "/Users/jimburer/Git/cryptography/python_library/data/data_transformation/type_conversion/byte_conversion.py", "exc_info": "Traceback (most recent call last):\n  File \"/Users/jimburer/Git/cryptography/python_library/data/data_transformation/type_conversion/byte_conversion.py\", line 6, in byte_conversion_def\n    in_bytes_as_int = int(in_bytes)\nValueError: invalid literal for int() with base 10: 'test'"}
{"message": "invalid literal for int() with base 10: 'test'", "time": "2020-06-30T17:34:50.373836", "level": "DEBUG", "filename": "byte_conversion.py", "funcName": "byte_conversion_def", "module": "byte_conversion", "pathname": "/Users/jimburer/Git/cryptography/python_library/data/data_transformation/type_conversion/byte_conversion.py", "exc_info": "Traceback (most recent call last):\n  File \"/Users/jimburer/Git/cryptography/python_library/data/data_transformation/type_conversion/byte_conversion.py\", line 6, in byte_conversion_def\n    in_bytes_as_int = int(in_bytes)\nValueError: invalid literal for int() with base 10: 'test'"}
{"message": "invalid literal for int() with base 10: 'test'", "time": "2020-06-30T17:34:50.610868", "level": "DEBUG", "filename": "byte_conversion.py", "funcName": "byte_conversion_def", "module": "byte_conversion", "pathname": "/Users/jimburer/Git/cryptography/python_library/data/data_transformation/type_conversion/byte_conversion.py", "exc_info": "Traceback (most recent call last):\n  File \"/Users/jimburer/Git/cryptography/python_library/data/data_transformation/type_conversion/byte_conversion.py\", line 6, in byte_conversion_def\n    in_bytes_as_int = int(in_bytes)\nValueError: invalid literal for int() with base 10: 'test'"}
{"message": "invalid literal for int() with base 10: 'test'", "time": "2020-06-30T17:34:51.131095", "level": "DEBUG", "filename": "byte_conversion.py", "funcName": "byte_conversion_def", "module": "byte_conversion", "pathname": "/Users/jimburer/Git/cryptography/python_library/data/data_transformation/type_conversion/byte_conversion.py", "exc_info": "Traceback (most recent call last):\n  File \"/Users/jimburer/Git/cryptography/python_library/data/data_transformation/type_conversion/byte_conversion.py\", line 6, in byte_conversion_def\n    in_bytes_as_int = int(in_bytes)\nValueError: invalid literal for int() with base 10: 'test'"}
{"message": "invalid literal for int() with base 10: 'test'", "time": "2020-06-30T17:34:51.542534", "level": "DEBUG", "filename": "byte_conversion.py", "funcName": "byte_conversion_def", "module": "byte_conversion", "pathname": "/Users/jimburer/Git/cryptography/python_library/data/data_transformation/type_conversion/byte_conversion.py", "exc_info": "Traceback (most recent call last):\n  File \"/Users/jimburer/Git/cryptography/python_library/data/data_transformation/type_conversion/byte_conversion.py\", line 6, in byte_conversion_def\n    in_bytes_as_int = int(in_bytes)\nValueError: invalid literal for int() with base 10: 'test'"}
{"message": "invalid literal for int() with base 10: 'gbar'", "time": "2020-06-30T17:34:51.748889", "level": "DEBUG", "filename": "byte_conversion.py", "funcName": "byte_conversion_def", "module": "byte_conversion", "pathname": "/Users/jimburer/Git/cryptography/python_library/data/data_transformation/type_conversion/byte_conversion.py", "exc_info": "Traceback (most recent call last):\n  File \"/Users/jimburer/Git/cryptography/python_library/data/data_transformation/type_conversion/byte_conversion.py\", line 6, in byte_conversion_def\n    in_bytes_as_int = int(in_bytes)\nValueError: invalid literal for int() with base 10: 'gbar'"}
{"message": "invalid literal for int() with base 10: 'test.bak'", "time": "2020-06-30T17:34:51.913047", "level": "DEBUG", "filename": "byte_conversion.py", "funcName": "byte_conversion_def", "module": "byte_conversion", "pathname": "/Users/jimburer/Git/cryptography/python_library/data/data_transformation/type_conversion/byte_conversion.py", "exc_info": "Traceback (most recent call last):\n  File \"/Users/jimburer/Git/cryptography/python_library/data/data_transformation/type_conversion/byte_conversion.py\", line 6, in byte_conversion_def\n    in_bytes_as_int = int(in_bytes)\nValueError: invalid literal for int() with base 10: 'test.bak'"}
{"message": "invalid literal for int() with base 10: 'test.backup'", "time": "2020-06-30T17:34:52.066798", "level": "DEBUG", "filename": "byte_conversion.py", "funcName": "byte_conversion_def", "module": "byte_conversion", "pathname": "/Users/jimburer/Git/cryptography/python_library/data/data_transformation/type_conversion/byte_conversion.py", "exc_info": "Traceback (most recent call last):\n  File \"/Users/jimburer/Git/cryptography/python_library/data/data_transformation/type_conversion/byte_conversion.py\", line 6, in byte_conversion_def\n    in_bytes_as_int = int(in_bytes)\nValueError: invalid literal for int() with base 10: 'test.backup'"}
{"message": "invalid literal for int() with base 10: 'test.bac'", "time": "2020-06-30T17:34:52.208189", "level": "DEBUG", "filename": "byte_conversion.py", "funcName": "byte_conversion_def", "module": "byte_conversion", "pathname": "/Users/jimburer/Git/cryptography/python_library/data/data_transformation/type_conversion/byte_conversion.py", "exc_info": "Traceback (most recent call last):\n  File \"/Users/jimburer/Git/cryptography/python_library/data/data_transformation/type_conversion/byte_conversion.py\", line 6, in byte_conversion_def\n    in_bytes_as_int = int(in_bytes)\nValueError: invalid literal for int() with base 10: 'test.bac'"}
{"message": "invalid literal for int() with base 10: 'test.zip'", "time": "2020-06-30T17:34:52.355793", "level": "DEBUG", "filename": "byte_conversion.py", "funcName": "byte_conversion_def", "module": "byte_conversion", "pathname": "/Users/jimburer/Git/cryptography/python_library/data/data_transformation/type_conversion/byte_conversion.py", "exc_info": "Traceback (most recent call last):\n  File \"/Users/jimburer/Git/cryptography/python_library/data/data_transformation/type_conversion/byte_conversion.py\", line 6, in byte_conversion_def\n    in_bytes_as_int = int(in_bytes)\nValueError: invalid literal for int() with base 10: 'test.zip'"}
{"message": "invalid literal for int() with base 10: 'test.tar'", "time": "2020-06-30T17:34:52.498721", "level": "DEBUG", "filename": "byte_conversion.py", "funcName": "byte_conversion_def", "module": "byte_conversion", "pathname": "/Users/jimburer/Git/cryptography/python_library/data/data_transformation/type_conversion/byte_conversion.py", "exc_info": "Traceback (most recent call last):\n  File \"/Users/jimburer/Git/cryptography/python_library/data/data_transformation/type_conversion/byte_conversion.py\", line 6, in byte_conversion_def\n    in_bytes_as_int = int(in_bytes)\nValueError: invalid literal for int() with base 10: 'test.tar'"}
{"message": "invalid literal for int() with base 10: 'test.jar'", "time": "2020-06-30T17:34:52.659075", "level": "DEBUG", "filename": "byte_conversion.py", "funcName": "byte_conversion_def", "module": "byte_conversion", "pathname": "/Users/jimburer/Git/cryptography/python_library/data/data_transformation/type_conversion/byte_conversion.py", "exc_info": "Traceback (most recent call last):\n  File \"/Users/jimburer/Git/cryptography/python_library/data/data_transformation/type_conversion/byte_conversion.py\", line 6, in byte_conversion_def\n    in_bytes_as_int = int(in_bytes)\nValueError: invalid literal for int() with base 10: 'test.jar'"}
{"message": "invalid literal for int() with base 10: 'test.log'", "time": "2020-06-30T17:34:52.838629", "level": "DEBUG", "filename": "byte_conversion.py", "funcName": "byte_conversion_def", "module": "byte_conversion", "pathname": "/Users/jimburer/Git/cryptography/python_library/data/data_transformation/type_conversion/byte_conversion.py", "exc_info": "Traceback (most recent call last):\n  File \"/Users/jimburer/Git/cryptography/python_library/data/data_transformation/type_conversion/byte_conversion.py\", line 6, in byte_conversion_def\n    in_bytes_as_int = int(in_bytes)\nValueError: invalid literal for int() with base 10: 'test.log'"}
{"message": "invalid literal for int() with base 10: 'test.swp'", "time": "2020-06-30T17:34:52.976708", "level": "DEBUG", "filename": "byte_conversion.py", "funcName": "byte_conversion_def", "module": "byte_conversion", "pathname": "/Users/jimburer/Git/cryptography/python_library/data/data_transformation/type_conversion/byte_conversion.py", "exc_info": "Traceback (most recent call last):\n  File \"/Users/jimburer/Git/cryptography/python_library/data/data_transformation/type_conversion/byte_conversion.py\", line 6, in byte_conversion_def\n    in_bytes_as_int = int(in_bytes)\nValueError: invalid literal for int() with base 10: 'test.swp'"}
{"message": "invalid literal for int() with base 10: 'test~'", "time": "2020-06-30T17:34:53.102589", "level": "DEBUG", "filename": "byte_conversion.py", "funcName": "byte_conversion_def", "module": "byte_conversion", "pathname": "/Users/jimburer/Git/cryptography/python_library/data/data_transformation/type_conversion/byte_conversion.py", "exc_info": "Traceback (most recent call last):\n  File \"/Users/jimburer/Git/cryptography/python_library/data/data_transformation/type_conversion/byte_conversion.py\", line 6, in byte_conversion_def\n    in_bytes_as_int = int(in_bytes)\nValueError: invalid literal for int() with base 10: 'test~'"}
{"message": "invalid literal for int() with base 10: 'test.old'", "time": "2020-06-30T17:34:53.235572", "level": "DEBUG", "filename": "byte_conversion.py", "funcName": "byte_conversion_def", "module": "byte_conversion", "pathname": "/Users/jimburer/Git/cryptography/python_library/data/data_transformation/type_conversion/byte_conversion.py", "exc_info": "Traceback (most recent call last):\n  File \"/Users/jimburer/Git/cryptography/python_library/data/data_transformation/type_conversion/byte_conversion.py\", line 6, in byte_conversion_def\n    in_bytes_as_int = int(in_bytes)\nValueError: invalid literal for int() with base 10: 'test.old'"}
{"message": "invalid literal for int() with base 10: 'test.~bk'", "time": "2020-06-30T17:34:53.359371", "level": "DEBUG", "filename": "byte_conversion.py", "funcName": "byte_conversion_def", "module": "byte_conversion", "pathname": "/Users/jimburer/Git/cryptography/python_library/data/data_transformation/type_conversion/byte_conversion.py", "exc_info": "Traceback (most recent call last):\n  File \"/Users/jimburer/Git/cryptography/python_library/data/data_transformation/type_conversion/byte_conversion.py\", line 6, in byte_conversion_def\n    in_bytes_as_int = int(in_bytes)\nValueError: invalid literal for int() with base 10: 'test.~bk'"}
{"message": "invalid literal for int() with base 10: 'test - Copy'", "time": "2020-06-30T17:34:53.492714", "level": "DEBUG", "filename": "byte_conversion.py", "funcName": "byte_conversion_def", "module": "byte_conversion", "pathname": "/Users/jimburer/Git/cryptography/python_library/data/data_transformation/type_conversion/byte_conversion.py", "exc_info": "Traceback (most recent call last):\n  File \"/Users/jimburer/Git/cryptography/python_library/data/data_transformation/type_conversion/byte_conversion.py\", line 6, in byte_conversion_def\n    in_bytes_as_int = int(in_bytes)\nValueError: invalid literal for int() with base 10: 'test - Copy'"}
{"message": "invalid literal for int() with base 10: 'test - Copy (2)'", "time": "2020-06-30T17:34:53.624598", "level": "DEBUG", "filename": "byte_conversion.py", "funcName": "byte_conversion_def", "module": "byte_conversion", "pathname": "/Users/jimburer/Git/cryptography/python_library/data/data_transformation/type_conversion/byte_conversion.py", "exc_info": "Traceback (most recent call last):\n  File \"/Users/jimburer/Git/cryptography/python_library/data/data_transformation/type_conversion/byte_conversion.py\", line 6, in byte_conversion_def\n    in_bytes_as_int = int(in_bytes)\nValueError: invalid literal for int() with base 10: 'test - Copy (2)'"}
{"message": "invalid literal for int() with base 10: 'test - Copy (3)'", "time": "2020-06-30T17:34:53.752116", "level": "DEBUG", "filename": "byte_conversion.py", "funcName": "byte_conversion_def", "module": "byte_conversion", "pathname": "/Users/jimburer/Git/cryptography/python_library/data/data_transformation/type_conversion/byte_conversion.py", "exc_info": "Traceback (most recent call last):\n  File \"/Users/jimburer/Git/cryptography/python_library/data/data_transformation/type_conversion/byte_conversion.py\", line 6, in byte_conversion_def\n    in_bytes_as_int = int(in_bytes)\nValueError: invalid literal for int() with base 10: 'test - Copy (3)'"}
{"message": "invalid literal for int() with base 10: 'testbackup'", "time": "2020-06-30T17:34:53.909048", "level": "DEBUG", "filename": "byte_conversion.py", "funcName": "byte_conversion_def", "module": "byte_conversion", "pathname": "/Users/jimburer/Git/cryptography/python_library/data/data_transformation/type_conversion/byte_conversion.py", "exc_info": "Traceback (most recent call last):\n  File \"/Users/jimburer/Git/cryptography/python_library/data/data_transformation/type_conversion/byte_conversion.py\", line 6, in byte_conversion_def\n    in_bytes_as_int = int(in_bytes)\nValueError: invalid literal for int() with base 10: 'testbackup'"}
{"message": "invalid literal for int() with base 10: 'Copy of test'", "time": "2020-06-30T17:34:54.053611", "level": "DEBUG", "filename": "byte_conversion.py", "funcName": "byte_conversion_def", "module": "byte_conversion", "pathname": "/Users/jimburer/Git/cryptography/python_library/data/data_transformation/type_conversion/byte_conversion.py", "exc_info": "Traceback (most recent call last):\n  File \"/Users/jimburer/Git/cryptography/python_library/data/data_transformation/type_conversion/byte_conversion.py\", line 6, in byte_conversion_def\n    in_bytes_as_int = int(in_bytes)\nValueError: invalid literal for int() with base 10: 'Copy of test'"}
{"message": "invalid literal for int() with base 10: 'Copy (2) of test'", "time": "2020-06-30T17:34:54.209205", "level": "DEBUG", "filename": "byte_conversion.py", "funcName": "byte_conversion_def", "module": "byte_conversion", "pathname": "/Users/jimburer/Git/cryptography/python_library/data/data_transformation/type_conversion/byte_conversion.py", "exc_info": "Traceback (most recent call last):\n  File \"/Users/jimburer/Git/cryptography/python_library/data/data_transformation/type_conversion/byte_conversion.py\", line 6, in byte_conversion_def\n    in_bytes_as_int = int(in_bytes)\nValueError: invalid literal for int() with base 10: 'Copy (2) of test'"}
{"message": "invalid literal for int() with base 10: 'Copy (3) of test'", "time": "2020-06-30T17:34:54.364671", "level": "DEBUG", "filename": "byte_conversion.py", "funcName": "byte_conversion_def", "module": "byte_conversion", "pathname": "/Users/jimburer/Git/cryptography/python_library/data/data_transformation/type_conversion/byte_conversion.py", "exc_info": "Traceback (most recent call last):\n  File \"/Users/jimburer/Git/cryptography/python_library/data/data_transformation/type_conversion/byte_conversion.py\", line 6, in byte_conversion_def\n    in_bytes_as_int = int(in_bytes)\nValueError: invalid literal for int() with base 10: 'Copy (3) of test'"}
{"message": "invalid literal for int() with base 10: 'test'", "time": "2020-06-30T17:34:54.645331", "level": "DEBUG", "filename": "byte_conversion.py", "funcName": "byte_conversion_def", "module": "byte_conversion", "pathname": "/Users/jimburer/Git/cryptography/python_library/data/data_transformation/type_conversion/byte_conversion.py", "exc_info": "Traceback (most recent call last):\n  File \"/Users/jimburer/Git/cryptography/python_library/data/data_transformation/type_conversion/byte_conversion.py\", line 6, in byte_conversion_def\n    in_bytes_as_int = int(in_bytes)\nValueError: invalid literal for int() with base 10: 'test'"}
{"message": "invalid literal for int() with base 10: 'test'", "time": "2020-06-30T17:34:54.846435", "level": "DEBUG", "filename": "byte_conversion.py", "funcName": "byte_conversion_def", "module": "byte_conversion", "pathname": "/Users/jimburer/Git/cryptography/python_library/data/data_transformation/type_conversion/byte_conversion.py", "exc_info": "Traceback (most recent call last):\n  File \"/Users/jimburer/Git/cryptography/python_library/data/data_transformation/type_conversion/byte_conversion.py\", line 6, in byte_conversion_def\n    in_bytes_as_int = int(in_bytes)\nValueError: invalid literal for int() with base 10: 'test'"}
{"message": "invalid literal for int() with base 10: 'test'", "time": "2020-06-30T17:34:55.056690", "level": "DEBUG", "filename": "byte_conversion.py", "funcName": "byte_conversion_def", "module": "byte_conversion", "pathname": "/Users/jimburer/Git/cryptography/python_library/data/data_transformation/type_conversion/byte_conversion.py", "exc_info": "Traceback (most recent call last):\n  File \"/Users/jimburer/Git/cryptography/python_library/data/data_transformation/type_conversion/byte_conversion.py\", line 6, in byte_conversion_def\n    in_bytes_as_int = int(in_bytes)\nValueError: invalid literal for int() with base 10: 'test'"}
{"message": "invalid literal for int() with base 10: 'test'", "time": "2020-06-30T17:34:55.417137", "level": "DEBUG", "filename": "byte_conversion.py", "funcName": "byte_conversion_def", "module": "byte_conversion", "pathname": "/Users/jimburer/Git/cryptography/python_library/data/data_transformation/type_conversion/byte_conversion.py", "exc_info": "Traceback (most recent call last):\n  File \"/Users/jimburer/Git/cryptography/python_library/data/data_transformation/type_conversion/byte_conversion.py\", line 6, in byte_conversion_def\n    in_bytes_as_int = int(in_bytes)\nValueError: invalid literal for int() with base 10: 'test'"}
{"message": "invalid literal for int() with base 10: 'test'", "time": "2020-06-30T17:34:55.581454", "level": "DEBUG", "filename": "byte_conversion.py", "funcName": "byte_conversion_def", "module": "byte_conversion", "pathname": "/Users/jimburer/Git/cryptography/python_library/data/data_transformation/type_conversion/byte_conversion.py", "exc_info": "Traceback (most recent call last):\n  File \"/Users/jimburer/Git/cryptography/python_library/data/data_transformation/type_conversion/byte_conversion.py\", line 6, in byte_conversion_def\n    in_bytes_as_int = int(in_bytes)\nValueError: invalid literal for int() with base 10: 'test'"}
{"message": "invalid literal for int() with base 10: 'test'", "time": "2020-06-30T17:34:55.750424", "level": "DEBUG", "filename": "byte_conversion.py", "funcName": "byte_conversion_def", "module": "byte_conversion", "pathname": "/Users/jimburer/Git/cryptography/python_library/data/data_transformation/type_conversion/byte_conversion.py", "exc_info": "Traceback (most recent call last):\n  File \"/Users/jimburer/Git/cryptography/python_library/data/data_transformation/type_conversion/byte_conversion.py\", line 6, in byte_conversion_def\n    in_bytes_as_int = int(in_bytes)\nValueError: invalid literal for int() with base 10: 'test'"}
{"message": "invalid literal for int() with base 10: 'test'", "time": "2020-06-30T17:34:55.879777", "level": "DEBUG", "filename": "byte_conversion.py", "funcName": "byte_conversion_def", "module": "byte_conversion", "pathname": "/Users/jimburer/Git/cryptography/python_library/data/data_transformation/type_conversion/byte_conversion.py", "exc_info": "Traceback (most recent call last):\n  File \"/Users/jimburer/Git/cryptography/python_library/data/data_transformation/type_conversion/byte_conversion.py\", line 6, in byte_conversion_def\n    in_bytes_as_int = int(in_bytes)\nValueError: invalid literal for int() with base 10: 'test'"}
{"message": "invalid literal for int() with base 10: 'trace.axd'", "time": "2020-06-30T17:34:56.033185", "level": "DEBUG", "filename": "byte_conversion.py", "funcName": "byte_conversion_def", "module": "byte_conversion", "pathname": "/Users/jimburer/Git/cryptography/python_library/data/data_transformation/type_conversion/byte_conversion.py", "exc_info": "Traceback (most recent call last):\n  File \"/Users/jimburer/Git/cryptography/python_library/data/data_transformation/type_conversion/byte_conversion.py\", line 6, in byte_conversion_def\n    in_bytes_as_int = int(in_bytes)\nValueError: invalid literal for int() with base 10: 'trace.axd'"}
{"message": "invalid literal for int() with base 10: '.htaccess'", "time": "2020-06-30T17:34:56.270829", "level": "DEBUG", "filename": "byte_conversion.py", "funcName": "byte_conversion_def", "module": "byte_conversion", "pathname": "/Users/jimburer/Git/cryptography/python_library/data/data_transformation/type_conversion/byte_conversion.py", "exc_info": "Traceback (most recent call last):\n  File \"/Users/jimburer/Git/cryptography/python_library/data/data_transformation/type_conversion/byte_conversion.py\", line 6, in byte_conversion_def\n    in_bytes_as_int = int(in_bytes)\nValueError: invalid literal for int() with base 10: '.htaccess'"}
{"message": "invalid literal for int() with base 10: 'test'", "time": "2020-06-30T17:34:56.421337", "level": "DEBUG", "filename": "byte_conversion.py", "funcName": "byte_conversion_def", "module": "byte_conversion", "pathname": "/Users/jimburer/Git/cryptography/python_library/data/data_transformation/type_conversion/byte_conversion.py", "exc_info": "Traceback (most recent call last):\n  File \"/Users/jimburer/Git/cryptography/python_library/data/data_transformation/type_conversion/byte_conversion.py\", line 6, in byte_conversion_def\n    in_bytes_as_int = int(in_bytes)\nValueError: invalid literal for int() with base 10: 'test'"}
{"message": "invalid literal for int() with base 10: 'test'", "time": "2020-06-30T17:34:56.577675", "level": "DEBUG", "filename": "byte_conversion.py", "funcName": "byte_conversion_def", "module": "byte_conversion", "pathname": "/Users/jimburer/Git/cryptography/python_library/data/data_transformation/type_conversion/byte_conversion.py", "exc_info": "Traceback (most recent call last):\n  File \"/Users/jimburer/Git/cryptography/python_library/data/data_transformation/type_conversion/byte_conversion.py\", line 6, in byte_conversion_def\n    in_bytes_as_int = int(in_bytes)\nValueError: invalid literal for int() with base 10: 'test'"}
{"message": "invalid literal for int() with base 10: 'test'", "time": "2020-06-30T17:34:56.832106", "level": "DEBUG", "filename": "byte_conversion.py", "funcName": "byte_conversion_def", "module": "byte_conversion", "pathname": "/Users/jimburer/Git/cryptography/python_library/data/data_transformation/type_conversion/byte_conversion.py", "exc_info": "Traceback (most recent call last):\n  File \"/Users/jimburer/Git/cryptography/python_library/data/data_transformation/type_conversion/byte_conversion.py\", line 6, in byte_conversion_def\n    in_bytes_as_int = int(in_bytes)\nValueError: invalid literal for int() with base 10: 'test'"}
{"message": "invalid literal for int() with base 10: 'test'", "time": "2020-06-30T17:34:57.015833", "level": "DEBUG", "filename": "byte_conversion.py", "funcName": "byte_conversion_def", "module": "byte_conversion", "pathname": "/Users/jimburer/Git/cryptography/python_library/data/data_transformation/type_conversion/byte_conversion.py", "exc_info": "Traceback (most recent call last):\n  File \"/Users/jimburer/Git/cryptography/python_library/data/data_transformation/type_conversion/byte_conversion.py\", line 6, in byte_conversion_def\n    in_bytes_as_int = int(in_bytes)\nValueError: invalid literal for int() with base 10: 'test'"}
{"message": "invalid literal for int() with base 10: 'test'", "time": "2020-06-30T17:34:57.165645", "level": "DEBUG", "filename": "byte_conversion.py", "funcName": "byte_conversion_def", "module": "byte_conversion", "pathname": "/Users/jimburer/Git/cryptography/python_library/data/data_transformation/type_conversion/byte_conversion.py", "exc_info": "Traceback (most recent call last):\n  File \"/Users/jimburer/Git/cryptography/python_library/data/data_transformation/type_conversion/byte_conversion.py\", line 6, in byte_conversion_def\n    in_bytes_as_int = int(in_bytes)\nValueError: invalid literal for int() with base 10: 'test'"}
{"message": "invalid literal for int() with base 10: 'test'", "time": "2020-06-30T17:34:57.299304", "level": "DEBUG", "filename": "byte_conversion.py", "funcName": "byte_conversion_def", "module": "byte_conversion", "pathname": "/Users/jimburer/Git/cryptography/python_library/data/data_transformation/type_conversion/byte_conversion.py", "exc_info": "Traceback (most recent call last):\n  File \"/Users/jimburer/Git/cryptography/python_library/data/data_transformation/type_conversion/byte_conversion.py\", line 6, in byte_conversion_def\n    in_bytes_as_int = int(in_bytes)\nValueError: invalid literal for int() with base 10: 'test'"}
{"message": "invalid literal for int() with base 10: 'test'", "time": "2020-06-30T17:34:57.436301", "level": "DEBUG", "filename": "byte_conversion.py", "funcName": "byte_conversion_def", "module": "byte_conversion", "pathname": "/Users/jimburer/Git/cryptography/python_library/data/data_transformation/type_conversion/byte_conversion.py", "exc_info": "Traceback (most recent call last):\n  File \"/Users/jimburer/Git/cryptography/python_library/data/data_transformation/type_conversion/byte_conversion.py\", line 6, in byte_conversion_def\n    in_bytes_as_int = int(in_bytes)\nValueError: invalid literal for int() with base 10: 'test'"}
{"message": "invalid literal for int() with base 10: 'test'", "time": "2020-06-30T17:34:57.608173", "level": "DEBUG", "filename": "byte_conversion.py", "funcName": "byte_conversion_def", "module": "byte_conversion", "pathname": "/Users/jimburer/Git/cryptography/python_library/data/data_transformation/type_conversion/byte_conversion.py", "exc_info": "Traceback (most recent call last):\n  File \"/Users/jimburer/Git/cryptography/python_library/data/data_transformation/type_conversion/byte_conversion.py\", line 6, in byte_conversion_def\n    in_bytes_as_int = int(in_bytes)\nValueError: invalid literal for int() with base 10: 'test'"}
{"message": "invalid literal for int() with base 10: '.env'", "time": "2020-06-30T17:34:57.819184", "level": "DEBUG", "filename": "byte_conversion.py", "funcName": "byte_conversion_def", "module": "byte_conversion", "pathname": "/Users/jimburer/Git/cryptography/python_library/data/data_transformation/type_conversion/byte_conversion.py", "exc_info": "Traceback (most recent call last):\n  File \"/Users/jimburer/Git/cryptography/python_library/data/data_transformation/type_conversion/byte_conversion.py\", line 6, in byte_conversion_def\n    in_bytes_as_int = int(in_bytes)\nValueError: invalid literal for int() with base 10: '.env'"}
{"message": "invalid literal for int() with base 10: '123456akhj'", "time": "2020-07-02T13:55:35.733620", "level": "DEBUG", "filename": "byte_conversion.py", "funcName": "byte_conversion_def", "module": "byte_conversion", "pathname": "/Users/jimburer/Git/cryptography/python_library/data/data_transformation/type_conversion/byte_conversion.py", "exc_info": "Traceback (most recent call last):\n  File \"/Users/jimburer/Git/cryptography/python_library/data/data_transformation/type_conversion/byte_conversion.py\", line 6, in byte_conversion_def\n    in_bytes_as_int = int(in_bytes)\nValueError: invalid literal for int() with base 10: '123456akhj'"}
{"message": "invalid literal for int() with base 10: '123456akhj'", "time": "2020-07-02T13:56:35.779631", "level": "DEBUG", "filename": "byte_conversion.py", "funcName": "byte_conversion_def", "module": "byte_conversion", "pathname": "/Users/jimburer/Git/cryptography/python_library/data/data_transformation/type_conversion/byte_conversion.py", "exc_info": "Traceback (most recent call last):\n  File \"/Users/jimburer/Git/cryptography/python_library/data/data_transformation/type_conversion/byte_conversion.py\", line 6, in byte_conversion_def\n    in_bytes_as_int = int(in_bytes)\nValueError: invalid literal for int() with base 10: '123456akhj'"}
{"message": "invalid literal for int() with base 10: '123456akhj'", "time": "2020-07-02T14:00:39.019864", "level": "DEBUG", "filename": "byte_conversion.py", "funcName": "byte_conversion_def", "module": "byte_conversion", "pathname": "/Users/jimburer/Git/cryptography/python_library/data/data_transformation/type_conversion/byte_conversion.py", "exc_info": "Traceback (most recent call last):\n  File \"/Users/jimburer/Git/cryptography/python_library/data/data_transformation/type_conversion/byte_conversion.py\", line 6, in byte_conversion_def\n    in_bytes_as_int = int(in_bytes)\nValueError: invalid literal for int() with base 10: '123456akhj'"}
{"message": "invalid literal for int() with base 10: '123456akhj'", "time": "2020-07-02T14:40:19.420001", "level": "DEBUG", "filename": "byte_conversion.py", "funcName": "byte_conversion_def", "module": "byte_conversion", "pathname": "/Users/jimburer/Git/cryptography/python_library/data/data_transformation/type_conversion/byte_conversion.py", "exc_info": "Traceback (most recent call last):\n  File \"/Users/jimburer/Git/cryptography/python_library/data/data_transformation/type_conversion/byte_conversion.py\", line 6, in byte_conversion_def\n    in_bytes_as_int = int(in_bytes)\nValueError: invalid literal for int() with base 10: '123456akhj'"}
{"message": "data must be bytes", "time": "2020-07-02T14:40:19.423183", "level": "DEBUG", "filename": "encryption.py", "funcName": "encryption_def", "module": "encryption", "pathname": "/Users/jimburer/Git/cryptography/python_library/data/data_transformation/data_confidentiality/encryption/encryption.py", "exc_info": "Traceback (most recent call last):\n  File \"/Users/jimburer/Git/cryptography/python_library/data/data_transformation/data_confidentiality/encryption/encryption.py\", line 25, in encryption_def\n    ciphertext = encryption_object.encrypt(data)\n  File \"/Users/jimburer/Git/cryptography/.venv/lib/python3.8/site-packages/cryptography/fernet.py\", line 52, in encrypt\n    return self._encrypt_from_parts(data, current_time, iv)\n  File \"/Users/jimburer/Git/cryptography/.venv/lib/python3.8/site-packages/cryptography/fernet.py\", line 55, in _encrypt_from_parts\n    utils._check_bytes(\"data\", data)\n  File \"/Users/jimburer/Git/cryptography/.venv/lib/python3.8/site-packages/cryptography/utils.py\", line 31, in _check_bytes\n    raise TypeError(\"{} must be bytes\".format(name))\nTypeError: data must be bytes"}
{"message": "invalid literal for int() with base 10: '123456akhj'", "time": "2020-07-02T14:41:29.858112", "level": "DEBUG", "filename": "byte_conversion.py", "funcName": "byte_conversion_def", "module": "byte_conversion", "pathname": "/Users/jimburer/Git/cryptography/python_library/data/data_transformation/type_conversion/byte_conversion.py", "exc_info": "Traceback (most recent call last):\n  File \"/Users/jimburer/Git/cryptography/python_library/data/data_transformation/type_conversion/byte_conversion.py\", line 6, in byte_conversion_def\n    in_bytes_as_int = int(in_bytes)\nValueError: invalid literal for int() with base 10: '123456akhj'"}
{"message": "invalid literal for int() with base 10: '123456akhj'", "time": "2020-07-02T16:09:57.669564", "level": "DEBUG", "filename": "byte_conversion.py", "funcName": "byte_conversion_def", "module": "byte_conversion", "pathname": "/Users/jimburer/Git/cryptography/python_library/data/data_transformation/type_conversion/byte_conversion.py", "exc_info": "Traceback (most recent call last):\n  File \"/Users/jimburer/Git/cryptography/python_library/data/data_transformation/type_conversion/byte_conversion.py\", line 6, in byte_conversion_def\n    in_bytes_as_int = int(in_bytes)\nValueError: invalid literal for int() with base 10: '123456akhj'"}
{"message": "invalid literal for int() with base 10: '123456akhj'", "time": "2020-07-02T18:21:51.202811", "level": "DEBUG", "filename": "byte_conversion.py", "funcName": "byte_conversion_def", "module": "byte_conversion", "pathname": "/Users/jimburer/Git/cryptography/python_library/data/data_transformation/type_conversion/byte_conversion.py", "exc_info": "Traceback (most recent call last):\n  File \"/Users/jimburer/Git/cryptography/python_library/data/data_transformation/type_conversion/byte_conversion.py\", line 6, in byte_conversion_def\n    in_bytes_as_int = int(in_bytes)\nValueError: invalid literal for int() with base 10: '123456akhj'"}
{"message": "invalid literal for int() with base 10: 'dsjh;ljahsdfkjh'", "time": "2020-07-02T18:30:13.252656", "level": "DEBUG", "filename": "byte_conversion.py", "funcName": "byte_conversion_def", "module": "byte_conversion", "pathname": "/Users/jimburer/Git/cryptography/python_library/data/data_transformation/type_conversion/byte_conversion.py", "exc_info": "Traceback (most recent call last):\n  File \"/Users/jimburer/Git/cryptography/python_library/data/data_transformation/type_conversion/byte_conversion.py\", line 6, in byte_conversion_def\n    in_bytes_as_int = int(in_bytes)\nValueError: invalid literal for int() with base 10: 'dsjh;ljahsdfkjh'"}
{"message": "invalid literal for int() with base 10: 'dsjh;ljahsdfkjh7666'", "time": "2020-07-02T18:30:20.301115", "level": "DEBUG", "filename": "byte_conversion.py", "funcName": "byte_conversion_def", "module": "byte_conversion", "pathname": "/Users/jimburer/Git/cryptography/python_library/data/data_transformation/type_conversion/byte_conversion.py", "exc_info": "Traceback (most recent call last):\n  File \"/Users/jimburer/Git/cryptography/python_library/data/data_transformation/type_conversion/byte_conversion.py\", line 6, in byte_conversion_def\n    in_bytes_as_int = int(in_bytes)\nValueError: invalid literal for int() with base 10: 'dsjh;ljahsdfkjh7666'"}
{"message": "invalid literal for int() with base 10: 'dsjh;ljahsdfkjh7666'", "time": "2020-07-02T18:38:57.273374", "level": "DEBUG", "filename": "byte_conversion.py", "funcName": "byte_conversion_def", "module": "byte_conversion", "pathname": "/Users/jimburer/Git/cryptography/python_library/data/data_transformation/type_conversion/byte_conversion.py", "exc_info": "Traceback (most recent call last):\n  File \"/Users/jimburer/Git/cryptography/python_library/data/data_transformation/type_conversion/byte_conversion.py\", line 6, in byte_conversion_def\n    in_bytes_as_int = int(in_bytes)\nValueError: invalid literal for int() with base 10: 'dsjh;ljahsdfkjh7666'"}
{"message": "invalid literal for int() with base 10: 'dsjh;ljahsdfkjh7666'", "time": "2020-07-02T18:40:06.471086", "level": "DEBUG", "filename": "byte_conversion.py", "funcName": "byte_conversion_def", "module": "byte_conversion", "pathname": "/Users/jimburer/Git/cryptography/python_library/data/data_transformation/type_conversion/byte_conversion.py", "exc_info": "Traceback (most recent call last):\n  File \"/Users/jimburer/Git/cryptography/python_library/data/data_transformation/type_conversion/byte_conversion.py\", line 6, in byte_conversion_def\n    in_bytes_as_int = int(in_bytes)\nValueError: invalid literal for int() with base 10: 'dsjh;ljahsdfkjh7666'"}
{"message": "invalid literal for int() with base 10: 'dsjh;ljahsdfkjh7666'", "time": "2020-07-02T18:41:32.456331", "level": "DEBUG", "filename": "byte_conversion.py", "funcName": "byte_conversion_def", "module": "byte_conversion", "pathname": "/Users/jimburer/Git/cryptography/python_library/data/data_transformation/type_conversion/byte_conversion.py", "exc_info": "Traceback (most recent call last):\n  File \"/Users/jimburer/Git/cryptography/python_library/data/data_transformation/type_conversion/byte_conversion.py\", line 6, in byte_conversion_def\n    in_bytes_as_int = int(in_bytes)\nValueError: invalid literal for int() with base 10: 'dsjh;ljahsdfkjh7666'"}
{"message": "invalid literal for int() with base 10: 'dsjh'", "time": "2020-07-02T18:41:40.112923", "level": "DEBUG", "filename": "byte_conversion.py", "funcName": "byte_conversion_def", "module": "byte_conversion", "pathname": "/Users/jimburer/Git/cryptography/python_library/data/data_transformation/type_conversion/byte_conversion.py", "exc_info": "Traceback (most recent call last):\n  File \"/Users/jimburer/Git/cryptography/python_library/data/data_transformation/type_conversion/byte_conversion.py\", line 6, in byte_conversion_def\n    in_bytes_as_int = int(in_bytes)\nValueError: invalid literal for int() with base 10: 'dsjh'"}
{"message": "invalid literal for int() with base 10: '<a value>'", "time": "2020-07-02T18:42:32.653658", "level": "DEBUG", "filename": "byte_conversion.py", "funcName": "byte_conversion_def", "module": "byte_conversion", "pathname": "/Users/jimburer/Git/cryptography/python_library/data/data_transformation/type_conversion/byte_conversion.py", "exc_info": "Traceback (most recent call last):\n  File \"/Users/jimburer/Git/cryptography/python_library/data/data_transformation/type_conversion/byte_conversion.py\", line 6, in byte_conversion_def\n    in_bytes_as_int = int(in_bytes)\nValueError: invalid literal for int() with base 10: '<a value>'"}
{"message": "invalid literal for int() with base 10: '<a value>'", "time": "2020-07-02T18:45:27.847572", "level": "DEBUG", "filename": "byte_conversion.py", "funcName": "byte_conversion_def", "module": "byte_conversion", "pathname": "/Users/jimburer/Git/cryptography/python_library/data/data_transformation/type_conversion/byte_conversion.py", "exc_info": "Traceback (most recent call last):\n  File \"/Users/jimburer/Git/cryptography/python_library/data/data_transformation/type_conversion/byte_conversion.py\", line 6, in byte_conversion_def\n    in_bytes_as_int = int(in_bytes)\nValueError: invalid literal for int() with base 10: '<a value>'"}
{"message": "invalid literal for int() with base 10: '<a value>'", "time": "2020-07-02T18:54:25.129657", "level": "DEBUG", "filename": "byte_conversion.py", "funcName": "byte_conversion_def", "module": "byte_conversion", "pathname": "/Users/jimburer/Git/cryptography/python_library/data/data_transformation/type_conversion/byte_conversion.py", "exc_info": "Traceback (most recent call last):\n  File \"/Users/jimburer/Git/cryptography/python_library/data/data_transformation/type_conversion/byte_conversion.py\", line 6, in byte_conversion_def\n    in_bytes_as_int = int(in_bytes)\nValueError: invalid literal for int() with base 10: '<a value>'"}
{"message": "invalid literal for int() with base 10: '<a value>'", "time": "2020-07-02T18:54:49.026539", "level": "DEBUG", "filename": "byte_conversion.py", "funcName": "byte_conversion_def", "module": "byte_conversion", "pathname": "/Users/jimburer/Git/cryptography/python_library/data/data_transformation/type_conversion/byte_conversion.py", "exc_info": "Traceback (most recent call last):\n  File \"/Users/jimburer/Git/cryptography/python_library/data/data_transformation/type_conversion/byte_conversion.py\", line 6, in byte_conversion_def\n    in_bytes_as_int = int(in_bytes)\nValueError: invalid literal for int() with base 10: '<a value>'"}
{"message": "invalid literal for int() with base 10: '<a value>'", "time": "2020-07-02T19:43:25.839279", "level": "DEBUG", "filename": "byte_conversion.py", "funcName": "byte_conversion_def", "module": "byte_conversion", "pathname": "/Users/jimburer/Git/cryptography/python_library/data/data_transformation/type_conversion/byte_conversion.py", "exc_info": "Traceback (most recent call last):\n  File \"/Users/jimburer/Git/cryptography/python_library/data/data_transformation/type_conversion/byte_conversion.py\", line 6, in byte_conversion_def\n    in_bytes_as_int = int(in_bytes)\nValueError: invalid literal for int() with base 10: '<a value>'"}
{"message": "invalid literal for int() with base 10: 'test'", "time": "2020-07-02T19:47:10.748159", "level": "DEBUG", "filename": "byte_conversion.py", "funcName": "byte_conversion_def", "module": "byte_conversion", "pathname": "/Users/jimburer/Git/cryptography/python_library/data/data_transformation/type_conversion/byte_conversion.py", "exc_info": "Traceback (most recent call last):\n  File \"/Users/jimburer/Git/cryptography/python_library/data/data_transformation/type_conversion/byte_conversion.py\", line 6, in byte_conversion_def\n    in_bytes_as_int = int(in_bytes)\nValueError: invalid literal for int() with base 10: 'test'"}
{"message": "invalid literal for int() with base 10: 'password'", "time": "2020-07-03T17:55:02.731023", "level": "DEBUG", "filename": "byte_conversion.py", "funcName": "byte_conversion_def", "module": "byte_conversion", "pathname": "/Users/jimburer/GitHub/cryptography/python_library/data/data_transformation/type_conversion/byte_conversion.py", "exc_info": "Traceback (most recent call last):\n  File \"/Users/jimburer/GitHub/cryptography/python_library/data/data_transformation/type_conversion/byte_conversion.py\", line 6, in byte_conversion_def\n    in_bytes_as_int = int(in_bytes)\nValueError: invalid literal for int() with base 10: 'password'"}
{"message": "invalid literal for int() with base 10: 'password'", "time": "2020-07-03T18:02:25.975084", "level": "DEBUG", "filename": "byte_conversion.py", "funcName": "byte_conversion_def", "module": "byte_conversion", "pathname": "/Users/jimburer/GitHub/cryptography/python_library/data/data_transformation/type_conversion/byte_conversion.py", "exc_info": "Traceback (most recent call last):\n  File \"/Users/jimburer/GitHub/cryptography/python_library/data/data_transformation/type_conversion/byte_conversion.py\", line 6, in byte_conversion_def\n    in_bytes_as_int = int(in_bytes)\nValueError: invalid literal for int() with base 10: 'password'"}
{"message": "int() argument must be a string, a bytes-like object or a number, not 'AuthenticatorStorageForm'", "time": "2020-07-03T18:26:54.865621", "level": "DEBUG", "filename": "byte_conversion.py", "funcName": "byte_conversion_def", "module": "byte_conversion", "pathname": "/Users/jimburer/GitHub/cryptography/python_library/data/data_transformation/type_conversion/byte_conversion.py", "exc_info": "Traceback (most recent call last):\n  File \"/Users/jimburer/GitHub/cryptography/python_library/data/data_transformation/type_conversion/byte_conversion.py\", line 6, in byte_conversion_def\n    in_bytes_as_int = int(in_bytes)\nTypeError: int() argument must be a string, a bytes-like object or a number, not 'AuthenticatorStorageForm'"}
{"message": "'AuthenticatorStorageForm' object has no attribute 'encode'", "time": "2020-07-03T18:26:54.866330", "level": "DEBUG", "filename": "byte_conversion.py", "funcName": "byte_conversion_def", "module": "byte_conversion", "pathname": "/Users/jimburer/GitHub/cryptography/python_library/data/data_transformation/type_conversion/byte_conversion.py", "exc_info": "Traceback (most recent call last):\n  File \"/Users/jimburer/GitHub/cryptography/python_library/data/data_transformation/type_conversion/byte_conversion.py\", line 13, in byte_conversion_def\n    as_bytes = in_bytes.encode('utf-8')\nAttributeError: 'AuthenticatorStorageForm' object has no attribute 'encode'"}
{"message": "a bytes-like object is required, not 'NoneType'", "time": "2020-07-03T18:26:54.866526", "level": "DEBUG", "filename": "derived_secure_hash.py", "funcName": "derived_secure_hash_def", "module": "derived_secure_hash", "pathname": "/Users/jimburer/GitHub/cryptography/python_library/data/data_transformation/data_confidentiality/hash/secure_hash/derived_secure_hash/derived_secure_hash.py", "exc_info": "Traceback (most recent call last):\n  File \"/Users/jimburer/GitHub/cryptography/python_library/data/data_transformation/data_confidentiality/hash/secure_hash/derived_secure_hash/derived_secure_hash.py\", line 42, in derived_secure_hash_def\n    dk = hashlib.pbkdf2_hmac(secure_hash_algorithm_name, authenticator_as_bytes, random_number_as_bytes, iterations, derived_secure_hash_length)\nTypeError: a bytes-like object is required, not 'NoneType'"}
{"message": "int() argument must be a string, a bytes-like object or a number, not 'AuthenticatorStorageForm'", "time": "2020-07-03T18:27:22.652628", "level": "DEBUG", "filename": "byte_conversion.py", "funcName": "byte_conversion_def", "module": "byte_conversion", "pathname": "/Users/jimburer/GitHub/cryptography/python_library/data/data_transformation/type_conversion/byte_conversion.py", "exc_info": "Traceback (most recent call last):\n  File \"/Users/jimburer/GitHub/cryptography/python_library/data/data_transformation/type_conversion/byte_conversion.py\", line 6, in byte_conversion_def\n    in_bytes_as_int = int(in_bytes)\nTypeError: int() argument must be a string, a bytes-like object or a number, not 'AuthenticatorStorageForm'"}
{"message": "'AuthenticatorStorageForm' object has no attribute 'encode'", "time": "2020-07-03T18:27:22.652914", "level": "DEBUG", "filename": "byte_conversion.py", "funcName": "byte_conversion_def", "module": "byte_conversion", "pathname": "/Users/jimburer/GitHub/cryptography/python_library/data/data_transformation/type_conversion/byte_conversion.py", "exc_info": "Traceback (most recent call last):\n  File \"/Users/jimburer/GitHub/cryptography/python_library/data/data_transformation/type_conversion/byte_conversion.py\", line 13, in byte_conversion_def\n    as_bytes = in_bytes.encode('utf-8')\nAttributeError: 'AuthenticatorStorageForm' object has no attribute 'encode'"}
{"message": "a bytes-like object is required, not 'NoneType'", "time": "2020-07-03T18:27:22.653069", "level": "DEBUG", "filename": "derived_secure_hash.py", "funcName": "derived_secure_hash_def", "module": "derived_secure_hash", "pathname": "/Users/jimburer/GitHub/cryptography/python_library/data/data_transformation/data_confidentiality/hash/secure_hash/derived_secure_hash/derived_secure_hash.py", "exc_info": "Traceback (most recent call last):\n  File \"/Users/jimburer/GitHub/cryptography/python_library/data/data_transformation/data_confidentiality/hash/secure_hash/derived_secure_hash/derived_secure_hash.py\", line 42, in derived_secure_hash_def\n    dk = hashlib.pbkdf2_hmac(secure_hash_algorithm_name, authenticator_as_bytes, random_number_as_bytes, iterations, derived_secure_hash_length)\nTypeError: a bytes-like object is required, not 'NoneType'"}
{"message": "invalid literal for int() with base 10: 'this new password'", "time": "2020-07-03T18:58:53.948937", "level": "DEBUG", "filename": "byte_conversion.py", "funcName": "byte_conversion_def", "module": "byte_conversion", "pathname": "/Users/jimburer/GitHub/cryptography/python_library/data/data_transformation/type_conversion/byte_conversion.py", "exc_info": "Traceback (most recent call last):\n  File \"/Users/jimburer/GitHub/cryptography/python_library/data/data_transformation/type_conversion/byte_conversion.py\", line 6, in byte_conversion_def\n    in_bytes_as_int = int(in_bytes)\nValueError: invalid literal for int() with base 10: 'this new password'"}
{"message": "invalid literal for int() with base 10: 'testes'", "time": "2020-07-03T18:59:38.392239", "level": "DEBUG", "filename": "byte_conversion.py", "funcName": "byte_conversion_def", "module": "byte_conversion", "pathname": "/Users/jimburer/GitHub/cryptography/python_library/data/data_transformation/type_conversion/byte_conversion.py", "exc_info": "Traceback (most recent call last):\n  File \"/Users/jimburer/GitHub/cryptography/python_library/data/data_transformation/type_conversion/byte_conversion.py\", line 6, in byte_conversion_def\n    in_bytes_as_int = int(in_bytes)\nValueError: invalid literal for int() with base 10: 'testes'"}
{"message": "invalid literal for int() with base 10: 'password'", "time": "2020-07-03T19:18:01.242203", "level": "DEBUG", "filename": "byte_conversion.py", "funcName": "byte_conversion_def", "module": "byte_conversion", "pathname": "/Users/jimburer/GitHub/cryptography/python_library/data/data_transformation/type_conversion/byte_conversion.py", "exc_info": "Traceback (most recent call last):\n  File \"/Users/jimburer/GitHub/cryptography/python_library/data/data_transformation/type_conversion/byte_conversion.py\", line 6, in byte_conversion_def\n    in_bytes_as_int = int(in_bytes)\nValueError: invalid literal for int() with base 10: 'password'"}
{"message": "invalid literal for int() with base 10: 'password'", "time": "2020-07-03T19:29:25.197032", "level": "DEBUG", "filename": "byte_conversion.py", "funcName": "byte_conversion_def", "module": "byte_conversion", "pathname": "/Users/jimburer/GitHub/cryptography/python_library/data/data_transformation/type_conversion/byte_conversion.py", "exc_info": "Traceback (most recent call last):\n  File \"/Users/jimburer/GitHub/cryptography/python_library/data/data_transformation/type_conversion/byte_conversion.py\", line 6, in byte_conversion_def\n    in_bytes_as_int = int(in_bytes)\nValueError: invalid literal for int() with base 10: 'password'"}
{"message": "invalid literal for int() with base 10: 'password'", "time": "2020-07-03T19:36:53.655758", "level": "DEBUG", "filename": "byte_conversion.py", "funcName": "byte_conversion_def", "module": "byte_conversion", "pathname": "/Users/jimburer/GitHub/cryptography/python_library/data/data_transformation/type_conversion/byte_conversion.py", "exc_info": "Traceback (most recent call last):\n  File \"/Users/jimburer/GitHub/cryptography/python_library/data/data_transformation/type_conversion/byte_conversion.py\", line 6, in byte_conversion_def\n    in_bytes_as_int = int(in_bytes)\nValueError: invalid literal for int() with base 10: 'password'"}
{"message": "invalid literal for int() with base 10: 'password'", "time": "2020-07-03T20:19:38.694163", "level": "DEBUG", "filename": "byte_conversion.py", "funcName": "byte_conversion_def", "module": "byte_conversion", "pathname": "/Users/jimburer/GitHub/cryptography/python_library/data/data_transformation/type_conversion/byte_conversion.py", "exc_info": "Traceback (most recent call last):\n  File \"/Users/jimburer/GitHub/cryptography/python_library/data/data_transformation/type_conversion/byte_conversion.py\", line 6, in byte_conversion_def\n    in_bytes_as_int = int(in_bytes)\nValueError: invalid literal for int() with base 10: 'password'"}
{"message": "invalid literal for int() with base 10: 'password'", "time": "2020-07-03T20:20:11.727130", "level": "DEBUG", "filename": "byte_conversion.py", "funcName": "byte_conversion_def", "module": "byte_conversion", "pathname": "/Users/jimburer/GitHub/cryptography/python_library/data/data_transformation/type_conversion/byte_conversion.py", "exc_info": "Traceback (most recent call last):\n  File \"/Users/jimburer/GitHub/cryptography/python_library/data/data_transformation/type_conversion/byte_conversion.py\", line 6, in byte_conversion_def\n    in_bytes_as_int = int(in_bytes)\nValueError: invalid literal for int() with base 10: 'password'"}
{"message": "invalid literal for int() with base 10: 'password'", "time": "2020-07-03T20:22:21.782383", "level": "DEBUG", "filename": "byte_conversion.py", "funcName": "byte_conversion_def", "module": "byte_conversion", "pathname": "/Users/jimburer/GitHub/cryptography/python_library/data/data_transformation/type_conversion/byte_conversion.py", "exc_info": "Traceback (most recent call last):\n  File \"/Users/jimburer/GitHub/cryptography/python_library/data/data_transformation/type_conversion/byte_conversion.py\", line 6, in byte_conversion_def\n    in_bytes_as_int = int(in_bytes)\nValueError: invalid literal for int() with base 10: 'password'"}
{"message": "invalid literal for int() with base 10: 'myp@$$w0rd'", "time": "2020-07-07T13:28:09.928659", "level": "DEBUG", "filename": "byte_conversion.py", "funcName": "byte_conversion_def", "module": "byte_conversion", "pathname": "/Users/jimburer/GitHub/cryptography/python_library/data/data_transformation/type_conversion/byte_conversion.py", "exc_info": "Traceback (most recent call last):\n  File \"/Users/jimburer/GitHub/cryptography/python_library/data/data_transformation/type_conversion/byte_conversion.py\", line 6, in byte_conversion_def\n    in_bytes_as_int = int(in_bytes)\nValueError: invalid literal for int() with base 10: 'myp@$$w0rd'"}
{"message": "invalid literal for int() with base 10: 'test'", "time": "2020-07-07T13:42:01.199168", "level": "DEBUG", "filename": "byte_conversion.py", "funcName": "byte_conversion_def", "module": "byte_conversion", "pathname": "/Users/jimburer/GitHub/cryptography/python_library/data/data_transformation/type_conversion/byte_conversion.py", "exc_info": "Traceback (most recent call last):\n  File \"/Users/jimburer/GitHub/cryptography/python_library/data/data_transformation/type_conversion/byte_conversion.py\", line 6, in byte_conversion_def\n    in_bytes_as_int = int(in_bytes)\nValueError: invalid literal for int() with base 10: 'test'"}
{"message": "invalid literal for int() with base 10: 'test'", "time": "2020-07-07T13:43:50.097549", "level": "DEBUG", "filename": "byte_conversion.py", "funcName": "byte_conversion_def", "module": "byte_conversion", "pathname": "/Users/jimburer/GitHub/cryptography/python_library/data/data_transformation/type_conversion/byte_conversion.py", "exc_info": "Traceback (most recent call last):\n  File \"/Users/jimburer/GitHub/cryptography/python_library/data/data_transformation/type_conversion/byte_conversion.py\", line 6, in byte_conversion_def\n    in_bytes_as_int = int(in_bytes)\nValueError: invalid literal for int() with base 10: 'test'"}
{"message": "invalid literal for int() with base 10: 'newone'", "time": "2020-07-07T13:44:31.766223", "level": "DEBUG", "filename": "byte_conversion.py", "funcName": "byte_conversion_def", "module": "byte_conversion", "pathname": "/Users/jimburer/GitHub/cryptography/python_library/data/data_transformation/type_conversion/byte_conversion.py", "exc_info": "Traceback (most recent call last):\n  File \"/Users/jimburer/GitHub/cryptography/python_library/data/data_transformation/type_conversion/byte_conversion.py\", line 6, in byte_conversion_def\n    in_bytes_as_int = int(in_bytes)\nValueError: invalid literal for int() with base 10: 'newone'"}
{"message": "invalid literal for int() with base 10: 'anotherone'", "time": "2020-07-07T13:44:44.466683", "level": "DEBUG", "filename": "byte_conversion.py", "funcName": "byte_conversion_def", "module": "byte_conversion", "pathname": "/Users/jimburer/GitHub/cryptography/python_library/data/data_transformation/type_conversion/byte_conversion.py", "exc_info": "Traceback (most recent call last):\n  File \"/Users/jimburer/GitHub/cryptography/python_library/data/data_transformation/type_conversion/byte_conversion.py\", line 6, in byte_conversion_def\n    in_bytes_as_int = int(in_bytes)\nValueError: invalid literal for int() with base 10: 'anotherone'"}
{"message": "invalid literal for int() with base 10: 'p@ssw0rd'", "time": "2020-07-07T19:48:07.704829", "level": "DEBUG", "filename": "byte_conversion.py", "funcName": "byte_conversion_def", "module": "byte_conversion", "pathname": "/Users/jimburer/GitHub/cryptography/python_library/data/data_transformation/type_conversion/byte_conversion.py", "exc_info": "Traceback (most recent call last):\n  File \"/Users/jimburer/GitHub/cryptography/python_library/data/data_transformation/type_conversion/byte_conversion.py\", line 6, in byte_conversion_def\n    in_bytes_as_int = int(in_bytes)\nValueError: invalid literal for int() with base 10: 'p@ssw0rd'"}
{"message": "invalid literal for int() with base 10: 'test'", "time": "2020-07-13T19:07:44.814939", "level": "DEBUG", "filename": "byte_conversion.py", "funcName": "byte_conversion_def", "module": "byte_conversion", "pathname": "/Users/jimburer/GitHub/cryptography/python_library/data/data_transformation/type_conversion/byte_conversion.py", "exc_info": "Traceback (most recent call last):\n  File \"/Users/jimburer/GitHub/cryptography/python_library/data/data_transformation/type_conversion/byte_conversion.py\", line 6, in byte_conversion_def\n    in_bytes_as_int = int(in_bytes)\nValueError: invalid literal for int() with base 10: 'test'"}
{"message": "invalid literal for int() with base 10: 'test'", "time": "2020-07-13T19:28:35.337262", "level": "DEBUG", "filename": "byte_conversion.py", "funcName": "byte_conversion_def", "module": "byte_conversion", "pathname": "/Users/jimburer/GitHub/cryptography/python_library/data/data_transformation/type_conversion/byte_conversion.py", "exc_info": "Traceback (most recent call last):\n  File \"/Users/jimburer/GitHub/cryptography/python_library/data/data_transformation/type_conversion/byte_conversion.py\", line 6, in byte_conversion_def\n    in_bytes_as_int = int(in_bytes)\nValueError: invalid literal for int() with base 10: 'test'"}
{"message": "invalid literal for int() with base 10: 'test'", "time": "2020-07-13T19:30:17.365903", "level": "DEBUG", "filename": "byte_conversion.py", "funcName": "byte_conversion_def", "module": "byte_conversion", "pathname": "/Users/jimburer/GitHub/cryptography/python_library/data/data_transformation/type_conversion/byte_conversion.py", "exc_info": "Traceback (most recent call last):\n  File \"/Users/jimburer/GitHub/cryptography/python_library/data/data_transformation/type_conversion/byte_conversion.py\", line 6, in byte_conversion_def\n    in_bytes_as_int = int(in_bytes)\nValueError: invalid literal for int() with base 10: 'test'"}
{"message": "invalid literal for int() with base 10: 'test'", "time": "2020-07-13T19:31:16.141222", "level": "DEBUG", "filename": "byte_conversion.py", "funcName": "byte_conversion_def", "module": "byte_conversion", "pathname": "/Users/jimburer/GitHub/cryptography/python_library/data/data_transformation/type_conversion/byte_conversion.py", "exc_info": "Traceback (most recent call last):\n  File \"/Users/jimburer/GitHub/cryptography/python_library/data/data_transformation/type_conversion/byte_conversion.py\", line 6, in byte_conversion_def\n    in_bytes_as_int = int(in_bytes)\nValueError: invalid literal for int() with base 10: 'test'"}
{"message": "int() argument must be a string, a bytes-like object or a number, not 'function'", "time": "2020-07-13T19:35:16.667125", "level": "DEBUG", "filename": "byte_conversion.py", "funcName": "byte_conversion_def", "module": "byte_conversion", "pathname": "/Users/jimburer/GitHub/cryptography/python_library/data/data_transformation/type_conversion/byte_conversion.py", "exc_info": "Traceback (most recent call last):\n  File \"/Users/jimburer/GitHub/cryptography/python_library/data/data_transformation/type_conversion/byte_conversion.py\", line 6, in byte_conversion_def\n    in_bytes_as_int = int(in_bytes)\nTypeError: int() argument must be a string, a bytes-like object or a number, not 'function'"}
{"message": "'function' object has no attribute 'encode'", "time": "2020-07-13T19:35:16.668109", "level": "DEBUG", "filename": "byte_conversion.py", "funcName": "byte_conversion_def", "module": "byte_conversion", "pathname": "/Users/jimburer/GitHub/cryptography/python_library/data/data_transformation/type_conversion/byte_conversion.py", "exc_info": "Traceback (most recent call last):\n  File \"/Users/jimburer/GitHub/cryptography/python_library/data/data_transformation/type_conversion/byte_conversion.py\", line 13, in byte_conversion_def\n    as_bytes = in_bytes.encode('utf-8')\nAttributeError: 'function' object has no attribute 'encode'"}
{"message": "a bytes-like object is required, not 'NoneType'", "time": "2020-07-13T19:35:16.668352", "level": "DEBUG", "filename": "derived_secure_hash.py", "funcName": "derived_secure_hash_def", "module": "derived_secure_hash", "pathname": "/Users/jimburer/GitHub/cryptography/python_library/data/data_transformation/data_confidentiality/hash/secure_hash/derived_secure_hash/derived_secure_hash.py", "exc_info": "Traceback (most recent call last):\n  File \"/Users/jimburer/GitHub/cryptography/python_library/data/data_transformation/data_confidentiality/hash/secure_hash/derived_secure_hash/derived_secure_hash.py\", line 42, in derived_secure_hash_def\n    dk = hashlib.pbkdf2_hmac(secure_hash_algorithm_name, authenticator_as_bytes, random_number_as_bytes, iterations, derived_secure_hash_length)\nTypeError: a bytes-like object is required, not 'NoneType'"}
{"message": "NOT NULL constraint failed: app_authenticatorstorage.authenticator", "time": "2020-07-13T19:35:16.670557", "level": "DEBUG", "filename": "authenticator_storage.py", "funcName": "authenticator_storage_def", "module": "authenticator_storage", "pathname": "/Users/jimburer/GitHub/cryptography/python_library/identity_and_access/identity/authenticator/authenticator_storage.py", "exc_info": "Traceback (most recent call last):\n  File \"/Users/jimburer/GitHub/cryptography/.venv/lib/python3.8/site-packages/django/db/backends/utils.py\", line 86, in _execute\n    return self.cursor.execute(sql, params)\n  File \"/Users/jimburer/GitHub/cryptography/.venv/lib/python3.8/site-packages/django/db/backends/sqlite3/base.py\", line 396, in execute\n    return Database.Cursor.execute(self, query, params)\nsqlite3.IntegrityError: NOT NULL constraint failed: app_authenticatorstorage.authenticator\n\nThe above exception was the direct cause of the following exception:\n\nTraceback (most recent call last):\n  File \"/Users/jimburer/GitHub/cryptography/python_library/identity_and_access/identity/authenticator/authenticator_storage.py\", line 14, in authenticator_storage_def\n    AuthenticatorStorage.objects.create(store_date=datetime.now(), authenticator=my_derived_secure_hash)\n  File \"/Users/jimburer/GitHub/cryptography/.venv/lib/python3.8/site-packages/django/db/models/manager.py\", line 82, in manager_method\n    return getattr(self.get_queryset(), name)(*args, **kwargs)\n  File \"/Users/jimburer/GitHub/cryptography/.venv/lib/python3.8/site-packages/django/db/models/query.py\", line 433, in create\n    obj.save(force_insert=True, using=self.db)\n  File \"/Users/jimburer/GitHub/cryptography/.venv/lib/python3.8/site-packages/django/db/models/base.py\", line 745, in save\n    self.save_base(using=using, force_insert=force_insert,\n  File \"/Users/jimburer/GitHub/cryptography/.venv/lib/python3.8/site-packages/django/db/models/base.py\", line 782, in save_base\n    updated = self._save_table(\n  File \"/Users/jimburer/GitHub/cryptography/.venv/lib/python3.8/site-packages/django/db/models/base.py\", line 887, in _save_table\n    results = self._do_insert(cls._base_manager, using, fields, returning_fields, raw)\n  File \"/Users/jimburer/GitHub/cryptography/.venv/lib/python3.8/site-packages/django/db/models/base.py\", line 924, in _do_insert\n    return manager._insert(\n  File \"/Users/jimburer/GitHub/cryptography/.venv/lib/python3.8/site-packages/django/db/models/manager.py\", line 82, in manager_method\n    return getattr(self.get_queryset(), name)(*args, **kwargs)\n  File \"/Users/jimburer/GitHub/cryptography/.venv/lib/python3.8/site-packages/django/db/models/query.py\", line 1204, in _insert\n    return query.get_compiler(using=using).execute_sql(returning_fields)\n  File \"/Users/jimburer/GitHub/cryptography/.venv/lib/python3.8/site-packages/django/db/models/sql/compiler.py\", line 1392, in execute_sql\n    cursor.execute(sql, params)\n  File \"/Users/jimburer/GitHub/cryptography/.venv/lib/python3.8/site-packages/django/db/backends/utils.py\", line 100, in execute\n    return super().execute(sql, params)\n  File \"/Users/jimburer/GitHub/cryptography/.venv/lib/python3.8/site-packages/django/db/backends/utils.py\", line 68, in execute\n    return self._execute_with_wrappers(sql, params, many=False, executor=self._execute)\n  File \"/Users/jimburer/GitHub/cryptography/.venv/lib/python3.8/site-packages/django/db/backends/utils.py\", line 77, in _execute_with_wrappers\n    return executor(sql, params, many, context)\n  File \"/Users/jimburer/GitHub/cryptography/.venv/lib/python3.8/site-packages/django/db/backends/utils.py\", line 86, in _execute\n    return self.cursor.execute(sql, params)\n  File \"/Users/jimburer/GitHub/cryptography/.venv/lib/python3.8/site-packages/django/db/utils.py\", line 90, in __exit__\n    raise dj_exc_value.with_traceback(traceback) from exc_value\n  File \"/Users/jimburer/GitHub/cryptography/.venv/lib/python3.8/site-packages/django/db/backends/utils.py\", line 86, in _execute\n    return self.cursor.execute(sql, params)\n  File \"/Users/jimburer/GitHub/cryptography/.venv/lib/python3.8/site-packages/django/db/backends/sqlite3/base.py\", line 396, in execute\n    return Database.Cursor.execute(self, query, params)\ndjango.db.utils.IntegrityError: NOT NULL constraint failed: app_authenticatorstorage.authenticator"}
{"message": "invalid literal for int() with base 10: 'test'", "time": "2020-07-13T19:35:16.721424", "level": "DEBUG", "filename": "byte_conversion.py", "funcName": "byte_conversion_def", "module": "byte_conversion", "pathname": "/Users/jimburer/GitHub/cryptography/python_library/data/data_transformation/type_conversion/byte_conversion.py", "exc_info": "Traceback (most recent call last):\n  File \"/Users/jimburer/GitHub/cryptography/python_library/data/data_transformation/type_conversion/byte_conversion.py\", line 6, in byte_conversion_def\n    in_bytes_as_int = int(in_bytes)\nValueError: invalid literal for int() with base 10: 'test'"}
{"message": "invalid literal for int() with base 10: b'16SyIVxWowKXriyAB_gVFGkuKC98NGe0L83_8UcXA0s='", "time": "2020-07-13T19:37:44.540566", "level": "DEBUG", "filename": "byte_conversion.py", "funcName": "byte_conversion_def", "module": "byte_conversion", "pathname": "/Users/jimburer/GitHub/cryptography/python_library/data/data_transformation/type_conversion/byte_conversion.py", "exc_info": "Traceback (most recent call last):\n  File \"/Users/jimburer/GitHub/cryptography/python_library/data/data_transformation/type_conversion/byte_conversion.py\", line 6, in byte_conversion_def\n    in_bytes_as_int = int(in_bytes)\nValueError: invalid literal for int() with base 10: b'16SyIVxWowKXriyAB_gVFGkuKC98NGe0L83_8UcXA0s='"}
{"message": "'bytes' object has no attribute 'encode'", "time": "2020-07-13T19:37:44.540921", "level": "DEBUG", "filename": "byte_conversion.py", "funcName": "byte_conversion_def", "module": "byte_conversion", "pathname": "/Users/jimburer/GitHub/cryptography/python_library/data/data_transformation/type_conversion/byte_conversion.py", "exc_info": "Traceback (most recent call last):\n  File \"/Users/jimburer/GitHub/cryptography/python_library/data/data_transformation/type_conversion/byte_conversion.py\", line 13, in byte_conversion_def\n    as_bytes = in_bytes.encode('utf-8')\nAttributeError: 'bytes' object has no attribute 'encode'"}
{"message": "a bytes-like object is required, not 'NoneType'", "time": "2020-07-13T19:37:44.541252", "level": "DEBUG", "filename": "derived_secure_hash.py", "funcName": "derived_secure_hash_def", "module": "derived_secure_hash", "pathname": "/Users/jimburer/GitHub/cryptography/python_library/data/data_transformation/data_confidentiality/hash/secure_hash/derived_secure_hash/derived_secure_hash.py", "exc_info": "Traceback (most recent call last):\n  File \"/Users/jimburer/GitHub/cryptography/python_library/data/data_transformation/data_confidentiality/hash/secure_hash/derived_secure_hash/derived_secure_hash.py\", line 42, in derived_secure_hash_def\n    dk = hashlib.pbkdf2_hmac(secure_hash_algorithm_name, authenticator_as_bytes, random_number_as_bytes, iterations, derived_secure_hash_length)\nTypeError: a bytes-like object is required, not 'NoneType'"}
{"message": "NOT NULL constraint failed: app_authenticatorstorage.authenticator", "time": "2020-07-13T19:37:44.544858", "level": "DEBUG", "filename": "authenticator_storage.py", "funcName": "authenticator_storage_def", "module": "authenticator_storage", "pathname": "/Users/jimburer/GitHub/cryptography/python_library/identity_and_access/identity/authenticator/authenticator_storage.py", "exc_info": "Traceback (most recent call last):\n  File \"/Users/jimburer/GitHub/cryptography/.venv/lib/python3.8/site-packages/django/db/backends/utils.py\", line 86, in _execute\n    return self.cursor.execute(sql, params)\n  File \"/Users/jimburer/GitHub/cryptography/.venv/lib/python3.8/site-packages/django/db/backends/sqlite3/base.py\", line 396, in execute\n    return Database.Cursor.execute(self, query, params)\nsqlite3.IntegrityError: NOT NULL constraint failed: app_authenticatorstorage.authenticator\n\nThe above exception was the direct cause of the following exception:\n\nTraceback (most recent call last):\n  File \"/Users/jimburer/GitHub/cryptography/python_library/identity_and_access/identity/authenticator/authenticator_storage.py\", line 14, in authenticator_storage_def\n    AuthenticatorStorage.objects.create(store_date=datetime.now(), authenticator=my_derived_secure_hash)\n  File \"/Users/jimburer/GitHub/cryptography/.venv/lib/python3.8/site-packages/django/db/models/manager.py\", line 82, in manager_method\n    return getattr(self.get_queryset(), name)(*args, **kwargs)\n  File \"/Users/jimburer/GitHub/cryptography/.venv/lib/python3.8/site-packages/django/db/models/query.py\", line 433, in create\n    obj.save(force_insert=True, using=self.db)\n  File \"/Users/jimburer/GitHub/cryptography/.venv/lib/python3.8/site-packages/django/db/models/base.py\", line 745, in save\n    self.save_base(using=using, force_insert=force_insert,\n  File \"/Users/jimburer/GitHub/cryptography/.venv/lib/python3.8/site-packages/django/db/models/base.py\", line 782, in save_base\n    updated = self._save_table(\n  File \"/Users/jimburer/GitHub/cryptography/.venv/lib/python3.8/site-packages/django/db/models/base.py\", line 887, in _save_table\n    results = self._do_insert(cls._base_manager, using, fields, returning_fields, raw)\n  File \"/Users/jimburer/GitHub/cryptography/.venv/lib/python3.8/site-packages/django/db/models/base.py\", line 924, in _do_insert\n    return manager._insert(\n  File \"/Users/jimburer/GitHub/cryptography/.venv/lib/python3.8/site-packages/django/db/models/manager.py\", line 82, in manager_method\n    return getattr(self.get_queryset(), name)(*args, **kwargs)\n  File \"/Users/jimburer/GitHub/cryptography/.venv/lib/python3.8/site-packages/django/db/models/query.py\", line 1204, in _insert\n    return query.get_compiler(using=using).execute_sql(returning_fields)\n  File \"/Users/jimburer/GitHub/cryptography/.venv/lib/python3.8/site-packages/django/db/models/sql/compiler.py\", line 1392, in execute_sql\n    cursor.execute(sql, params)\n  File \"/Users/jimburer/GitHub/cryptography/.venv/lib/python3.8/site-packages/django/db/backends/utils.py\", line 100, in execute\n    return super().execute(sql, params)\n  File \"/Users/jimburer/GitHub/cryptography/.venv/lib/python3.8/site-packages/django/db/backends/utils.py\", line 68, in execute\n    return self._execute_with_wrappers(sql, params, many=False, executor=self._execute)\n  File \"/Users/jimburer/GitHub/cryptography/.venv/lib/python3.8/site-packages/django/db/backends/utils.py\", line 77, in _execute_with_wrappers\n    return executor(sql, params, many, context)\n  File \"/Users/jimburer/GitHub/cryptography/.venv/lib/python3.8/site-packages/django/db/backends/utils.py\", line 86, in _execute\n    return self.cursor.execute(sql, params)\n  File \"/Users/jimburer/GitHub/cryptography/.venv/lib/python3.8/site-packages/django/db/utils.py\", line 90, in __exit__\n    raise dj_exc_value.with_traceback(traceback) from exc_value\n  File \"/Users/jimburer/GitHub/cryptography/.venv/lib/python3.8/site-packages/django/db/backends/utils.py\", line 86, in _execute\n    return self.cursor.execute(sql, params)\n  File \"/Users/jimburer/GitHub/cryptography/.venv/lib/python3.8/site-packages/django/db/backends/sqlite3/base.py\", line 396, in execute\n    return Database.Cursor.execute(self, query, params)\ndjango.db.utils.IntegrityError: NOT NULL constraint failed: app_authenticatorstorage.authenticator"}
{"message": "invalid literal for int() with base 10: 'test'", "time": "2020-07-13T19:37:44.600682", "level": "DEBUG", "filename": "byte_conversion.py", "funcName": "byte_conversion_def", "module": "byte_conversion", "pathname": "/Users/jimburer/GitHub/cryptography/python_library/data/data_transformation/type_conversion/byte_conversion.py", "exc_info": "Traceback (most recent call last):\n  File \"/Users/jimburer/GitHub/cryptography/python_library/data/data_transformation/type_conversion/byte_conversion.py\", line 6, in byte_conversion_def\n    in_bytes_as_int = int(in_bytes)\nValueError: invalid literal for int() with base 10: 'test'"}
{"message": "invalid literal for int() with base 10: b'PKTuzq4VrN4A8lmbNxtlaIjQQKPsOxzA136d0Dwhfp8='", "time": "2020-07-13T19:37:48.959643", "level": "DEBUG", "filename": "byte_conversion.py", "funcName": "byte_conversion_def", "module": "byte_conversion", "pathname": "/Users/jimburer/GitHub/cryptography/python_library/data/data_transformation/type_conversion/byte_conversion.py", "exc_info": "Traceback (most recent call last):\n  File \"/Users/jimburer/GitHub/cryptography/python_library/data/data_transformation/type_conversion/byte_conversion.py\", line 6, in byte_conversion_def\n    in_bytes_as_int = int(in_bytes)\nValueError: invalid literal for int() with base 10: b'PKTuzq4VrN4A8lmbNxtlaIjQQKPsOxzA136d0Dwhfp8='"}
{"message": "'bytes' object has no attribute 'encode'", "time": "2020-07-13T19:37:48.959856", "level": "DEBUG", "filename": "byte_conversion.py", "funcName": "byte_conversion_def", "module": "byte_conversion", "pathname": "/Users/jimburer/GitHub/cryptography/python_library/data/data_transformation/type_conversion/byte_conversion.py", "exc_info": "Traceback (most recent call last):\n  File \"/Users/jimburer/GitHub/cryptography/python_library/data/data_transformation/type_conversion/byte_conversion.py\", line 13, in byte_conversion_def\n    as_bytes = in_bytes.encode('utf-8')\nAttributeError: 'bytes' object has no attribute 'encode'"}
{"message": "a bytes-like object is required, not 'NoneType'", "time": "2020-07-13T19:37:48.960017", "level": "DEBUG", "filename": "derived_secure_hash.py", "funcName": "derived_secure_hash_def", "module": "derived_secure_hash", "pathname": "/Users/jimburer/GitHub/cryptography/python_library/data/data_transformation/data_confidentiality/hash/secure_hash/derived_secure_hash/derived_secure_hash.py", "exc_info": "Traceback (most recent call last):\n  File \"/Users/jimburer/GitHub/cryptography/python_library/data/data_transformation/data_confidentiality/hash/secure_hash/derived_secure_hash/derived_secure_hash.py\", line 42, in derived_secure_hash_def\n    dk = hashlib.pbkdf2_hmac(secure_hash_algorithm_name, authenticator_as_bytes, random_number_as_bytes, iterations, derived_secure_hash_length)\nTypeError: a bytes-like object is required, not 'NoneType'"}
{"message": "NOT NULL constraint failed: app_authenticatorstorage.authenticator", "time": "2020-07-13T19:37:48.961624", "level": "DEBUG", "filename": "authenticator_storage.py", "funcName": "authenticator_storage_def", "module": "authenticator_storage", "pathname": "/Users/jimburer/GitHub/cryptography/python_library/identity_and_access/identity/authenticator/authenticator_storage.py", "exc_info": "Traceback (most recent call last):\n  File \"/Users/jimburer/GitHub/cryptography/.venv/lib/python3.8/site-packages/django/db/backends/utils.py\", line 86, in _execute\n    return self.cursor.execute(sql, params)\n  File \"/Users/jimburer/GitHub/cryptography/.venv/lib/python3.8/site-packages/django/db/backends/sqlite3/base.py\", line 396, in execute\n    return Database.Cursor.execute(self, query, params)\nsqlite3.IntegrityError: NOT NULL constraint failed: app_authenticatorstorage.authenticator\n\nThe above exception was the direct cause of the following exception:\n\nTraceback (most recent call last):\n  File \"/Users/jimburer/GitHub/cryptography/python_library/identity_and_access/identity/authenticator/authenticator_storage.py\", line 14, in authenticator_storage_def\n    AuthenticatorStorage.objects.create(store_date=datetime.now(), authenticator=my_derived_secure_hash)\n  File \"/Users/jimburer/GitHub/cryptography/.venv/lib/python3.8/site-packages/django/db/models/manager.py\", line 82, in manager_method\n    return getattr(self.get_queryset(), name)(*args, **kwargs)\n  File \"/Users/jimburer/GitHub/cryptography/.venv/lib/python3.8/site-packages/django/db/models/query.py\", line 433, in create\n    obj.save(force_insert=True, using=self.db)\n  File \"/Users/jimburer/GitHub/cryptography/.venv/lib/python3.8/site-packages/django/db/models/base.py\", line 745, in save\n    self.save_base(using=using, force_insert=force_insert,\n  File \"/Users/jimburer/GitHub/cryptography/.venv/lib/python3.8/site-packages/django/db/models/base.py\", line 782, in save_base\n    updated = self._save_table(\n  File \"/Users/jimburer/GitHub/cryptography/.venv/lib/python3.8/site-packages/django/db/models/base.py\", line 887, in _save_table\n    results = self._do_insert(cls._base_manager, using, fields, returning_fields, raw)\n  File \"/Users/jimburer/GitHub/cryptography/.venv/lib/python3.8/site-packages/django/db/models/base.py\", line 924, in _do_insert\n    return manager._insert(\n  File \"/Users/jimburer/GitHub/cryptography/.venv/lib/python3.8/site-packages/django/db/models/manager.py\", line 82, in manager_method\n    return getattr(self.get_queryset(), name)(*args, **kwargs)\n  File \"/Users/jimburer/GitHub/cryptography/.venv/lib/python3.8/site-packages/django/db/models/query.py\", line 1204, in _insert\n    return query.get_compiler(using=using).execute_sql(returning_fields)\n  File \"/Users/jimburer/GitHub/cryptography/.venv/lib/python3.8/site-packages/django/db/models/sql/compiler.py\", line 1392, in execute_sql\n    cursor.execute(sql, params)\n  File \"/Users/jimburer/GitHub/cryptography/.venv/lib/python3.8/site-packages/django/db/backends/utils.py\", line 100, in execute\n    return super().execute(sql, params)\n  File \"/Users/jimburer/GitHub/cryptography/.venv/lib/python3.8/site-packages/django/db/backends/utils.py\", line 68, in execute\n    return self._execute_with_wrappers(sql, params, many=False, executor=self._execute)\n  File \"/Users/jimburer/GitHub/cryptography/.venv/lib/python3.8/site-packages/django/db/backends/utils.py\", line 77, in _execute_with_wrappers\n    return executor(sql, params, many, context)\n  File \"/Users/jimburer/GitHub/cryptography/.venv/lib/python3.8/site-packages/django/db/backends/utils.py\", line 86, in _execute\n    return self.cursor.execute(sql, params)\n  File \"/Users/jimburer/GitHub/cryptography/.venv/lib/python3.8/site-packages/django/db/utils.py\", line 90, in __exit__\n    raise dj_exc_value.with_traceback(traceback) from exc_value\n  File \"/Users/jimburer/GitHub/cryptography/.venv/lib/python3.8/site-packages/django/db/backends/utils.py\", line 86, in _execute\n    return self.cursor.execute(sql, params)\n  File \"/Users/jimburer/GitHub/cryptography/.venv/lib/python3.8/site-packages/django/db/backends/sqlite3/base.py\", line 396, in execute\n    return Database.Cursor.execute(self, query, params)\ndjango.db.utils.IntegrityError: NOT NULL constraint failed: app_authenticatorstorage.authenticator"}
{"message": "invalid literal for int() with base 10: 'test'", "time": "2020-07-13T19:37:48.962114", "level": "DEBUG", "filename": "byte_conversion.py", "funcName": "byte_conversion_def", "module": "byte_conversion", "pathname": "/Users/jimburer/GitHub/cryptography/python_library/data/data_transformation/type_conversion/byte_conversion.py", "exc_info": "Traceback (most recent call last):\n  File \"/Users/jimburer/GitHub/cryptography/python_library/data/data_transformation/type_conversion/byte_conversion.py\", line 6, in byte_conversion_def\n    in_bytes_as_int = int(in_bytes)\nValueError: invalid literal for int() with base 10: 'test'"}
{"message": "invalid literal for int() with base 10: b'pwFwT4pcD3YP97Xg1bNyrT9MawqJZ4LYDZTLXDT2jFo='", "time": "2020-07-13T19:39:17.405566", "level": "DEBUG", "filename": "byte_conversion.py", "funcName": "byte_conversion_def", "module": "byte_conversion", "pathname": "/Users/jimburer/GitHub/cryptography/python_library/data/data_transformation/type_conversion/byte_conversion.py", "exc_info": "Traceback (most recent call last):\n  File \"/Users/jimburer/GitHub/cryptography/python_library/data/data_transformation/type_conversion/byte_conversion.py\", line 6, in byte_conversion_def\n    in_bytes_as_int = int(in_bytes)\nValueError: invalid literal for int() with base 10: b'pwFwT4pcD3YP97Xg1bNyrT9MawqJZ4LYDZTLXDT2jFo='"}
{"message": "'bytes' object has no attribute 'encode'", "time": "2020-07-13T19:39:17.405873", "level": "DEBUG", "filename": "byte_conversion.py", "funcName": "byte_conversion_def", "module": "byte_conversion", "pathname": "/Users/jimburer/GitHub/cryptography/python_library/data/data_transformation/type_conversion/byte_conversion.py", "exc_info": "Traceback (most recent call last):\n  File \"/Users/jimburer/GitHub/cryptography/python_library/data/data_transformation/type_conversion/byte_conversion.py\", line 13, in byte_conversion_def\n    as_bytes = in_bytes.encode('utf-8')\nAttributeError: 'bytes' object has no attribute 'encode'"}
{"message": "a bytes-like object is required, not 'NoneType'", "time": "2020-07-13T19:39:17.406032", "level": "DEBUG", "filename": "derived_secure_hash.py", "funcName": "derived_secure_hash_def", "module": "derived_secure_hash", "pathname": "/Users/jimburer/GitHub/cryptography/python_library/data/data_transformation/data_confidentiality/hash/secure_hash/derived_secure_hash/derived_secure_hash.py", "exc_info": "Traceback (most recent call last):\n  File \"/Users/jimburer/GitHub/cryptography/python_library/data/data_transformation/data_confidentiality/hash/secure_hash/derived_secure_hash/derived_secure_hash.py\", line 42, in derived_secure_hash_def\n    dk = hashlib.pbkdf2_hmac(secure_hash_algorithm_name, authenticator_as_bytes, random_number_as_bytes, iterations, derived_secure_hash_length)\nTypeError: a bytes-like object is required, not 'NoneType'"}
{"message": "NOT NULL constraint failed: app_authenticatorstorage.authenticator", "time": "2020-07-13T19:39:17.408617", "level": "DEBUG", "filename": "authenticator_storage.py", "funcName": "authenticator_storage_def", "module": "authenticator_storage", "pathname": "/Users/jimburer/GitHub/cryptography/python_library/identity_and_access/identity/authenticator/authenticator_storage.py", "exc_info": "Traceback (most recent call last):\n  File \"/Users/jimburer/GitHub/cryptography/.venv/lib/python3.8/site-packages/django/db/backends/utils.py\", line 86, in _execute\n    return self.cursor.execute(sql, params)\n  File \"/Users/jimburer/GitHub/cryptography/.venv/lib/python3.8/site-packages/django/db/backends/sqlite3/base.py\", line 396, in execute\n    return Database.Cursor.execute(self, query, params)\nsqlite3.IntegrityError: NOT NULL constraint failed: app_authenticatorstorage.authenticator\n\nThe above exception was the direct cause of the following exception:\n\nTraceback (most recent call last):\n  File \"/Users/jimburer/GitHub/cryptography/python_library/identity_and_access/identity/authenticator/authenticator_storage.py\", line 14, in authenticator_storage_def\n    AuthenticatorStorage.objects.create(store_date=datetime.now(), authenticator=my_derived_secure_hash)\n  File \"/Users/jimburer/GitHub/cryptography/.venv/lib/python3.8/site-packages/django/db/models/manager.py\", line 82, in manager_method\n    return getattr(self.get_queryset(), name)(*args, **kwargs)\n  File \"/Users/jimburer/GitHub/cryptography/.venv/lib/python3.8/site-packages/django/db/models/query.py\", line 433, in create\n    obj.save(force_insert=True, using=self.db)\n  File \"/Users/jimburer/GitHub/cryptography/.venv/lib/python3.8/site-packages/django/db/models/base.py\", line 745, in save\n    self.save_base(using=using, force_insert=force_insert,\n  File \"/Users/jimburer/GitHub/cryptography/.venv/lib/python3.8/site-packages/django/db/models/base.py\", line 782, in save_base\n    updated = self._save_table(\n  File \"/Users/jimburer/GitHub/cryptography/.venv/lib/python3.8/site-packages/django/db/models/base.py\", line 887, in _save_table\n    results = self._do_insert(cls._base_manager, using, fields, returning_fields, raw)\n  File \"/Users/jimburer/GitHub/cryptography/.venv/lib/python3.8/site-packages/django/db/models/base.py\", line 924, in _do_insert\n    return manager._insert(\n  File \"/Users/jimburer/GitHub/cryptography/.venv/lib/python3.8/site-packages/django/db/models/manager.py\", line 82, in manager_method\n    return getattr(self.get_queryset(), name)(*args, **kwargs)\n  File \"/Users/jimburer/GitHub/cryptography/.venv/lib/python3.8/site-packages/django/db/models/query.py\", line 1204, in _insert\n    return query.get_compiler(using=using).execute_sql(returning_fields)\n  File \"/Users/jimburer/GitHub/cryptography/.venv/lib/python3.8/site-packages/django/db/models/sql/compiler.py\", line 1392, in execute_sql\n    cursor.execute(sql, params)\n  File \"/Users/jimburer/GitHub/cryptography/.venv/lib/python3.8/site-packages/django/db/backends/utils.py\", line 100, in execute\n    return super().execute(sql, params)\n  File \"/Users/jimburer/GitHub/cryptography/.venv/lib/python3.8/site-packages/django/db/backends/utils.py\", line 68, in execute\n    return self._execute_with_wrappers(sql, params, many=False, executor=self._execute)\n  File \"/Users/jimburer/GitHub/cryptography/.venv/lib/python3.8/site-packages/django/db/backends/utils.py\", line 77, in _execute_with_wrappers\n    return executor(sql, params, many, context)\n  File \"/Users/jimburer/GitHub/cryptography/.venv/lib/python3.8/site-packages/django/db/backends/utils.py\", line 86, in _execute\n    return self.cursor.execute(sql, params)\n  File \"/Users/jimburer/GitHub/cryptography/.venv/lib/python3.8/site-packages/django/db/utils.py\", line 90, in __exit__\n    raise dj_exc_value.with_traceback(traceback) from exc_value\n  File \"/Users/jimburer/GitHub/cryptography/.venv/lib/python3.8/site-packages/django/db/backends/utils.py\", line 86, in _execute\n    return self.cursor.execute(sql, params)\n  File \"/Users/jimburer/GitHub/cryptography/.venv/lib/python3.8/site-packages/django/db/backends/sqlite3/base.py\", line 396, in execute\n    return Database.Cursor.execute(self, query, params)\ndjango.db.utils.IntegrityError: NOT NULL constraint failed: app_authenticatorstorage.authenticator"}
{"message": "invalid literal for int() with base 10: b'yH2C4SO20Qp6f20cxXopO341uLL-J7Hhn2YDACFxzjY='", "time": "2020-07-13T19:39:17.446873", "level": "DEBUG", "filename": "byte_conversion.py", "funcName": "byte_conversion_def", "module": "byte_conversion", "pathname": "/Users/jimburer/GitHub/cryptography/python_library/data/data_transformation/type_conversion/byte_conversion.py", "exc_info": "Traceback (most recent call last):\n  File \"/Users/jimburer/GitHub/cryptography/python_library/data/data_transformation/type_conversion/byte_conversion.py\", line 6, in byte_conversion_def\n    in_bytes_as_int = int(in_bytes)\nValueError: invalid literal for int() with base 10: b'yH2C4SO20Qp6f20cxXopO341uLL-J7Hhn2YDACFxzjY='"}
{"message": "'bytes' object has no attribute 'encode'", "time": "2020-07-13T19:39:17.447062", "level": "DEBUG", "filename": "byte_conversion.py", "funcName": "byte_conversion_def", "module": "byte_conversion", "pathname": "/Users/jimburer/GitHub/cryptography/python_library/data/data_transformation/type_conversion/byte_conversion.py", "exc_info": "Traceback (most recent call last):\n  File \"/Users/jimburer/GitHub/cryptography/python_library/data/data_transformation/type_conversion/byte_conversion.py\", line 13, in byte_conversion_def\n    as_bytes = in_bytes.encode('utf-8')\nAttributeError: 'bytes' object has no attribute 'encode'"}
{"message": "data must be bytes", "time": "2020-07-13T19:39:17.447198", "level": "DEBUG", "filename": "encryption.py", "funcName": "encryption_def", "module": "encryption", "pathname": "/Users/jimburer/GitHub/cryptography/python_library/data/data_transformation/data_confidentiality/encryption/encryption.py", "exc_info": "Traceback (most recent call last):\n  File \"/Users/jimburer/GitHub/cryptography/python_library/data/data_transformation/data_confidentiality/encryption/encryption.py\", line 31, in encryption_def\n    ciphertext = encrypted_object.encrypt(data_as_bytes)\n  File \"/Users/jimburer/GitHub/cryptography/.venv/lib/python3.8/site-packages/cryptography/fernet.py\", line 52, in encrypt\n    return self._encrypt_from_parts(data, current_time, iv)\n  File \"/Users/jimburer/GitHub/cryptography/.venv/lib/python3.8/site-packages/cryptography/fernet.py\", line 55, in _encrypt_from_parts\n    utils._check_bytes(\"data\", data)\n  File \"/Users/jimburer/GitHub/cryptography/.venv/lib/python3.8/site-packages/cryptography/utils.py\", line 31, in _check_bytes\n    raise TypeError(\"{} must be bytes\".format(name))\nTypeError: data must be bytes"}
{"message": "local variable 'authenticator_as_bytes' referenced before assignment", "time": "2020-07-13T19:47:29.691890", "level": "DEBUG", "filename": "derived_secure_hash.py", "funcName": "derived_secure_hash_def", "module": "derived_secure_hash", "pathname": "/Users/jimburer/GitHub/cryptography/python_library/data/data_transformation/data_confidentiality/hash/secure_hash/derived_secure_hash/derived_secure_hash.py", "exc_info": "Traceback (most recent call last):\n  File \"/Users/jimburer/GitHub/cryptography/python_library/data/data_transformation/data_confidentiality/hash/secure_hash/derived_secure_hash/derived_secure_hash.py\", line 45, in derived_secure_hash_def\n    dk = hashlib.pbkdf2_hmac(secure_hash_algorithm_name, authenticator_as_bytes, random_number_as_bytes, iterations, derived_secure_hash_length)\nUnboundLocalError: local variable 'authenticator_as_bytes' referenced before assignment"}
{"message": "NOT NULL constraint failed: app_authenticatorstorage.authenticator", "time": "2020-07-13T19:47:29.695704", "level": "DEBUG", "filename": "authenticator_storage.py", "funcName": "authenticator_storage_def", "module": "authenticator_storage", "pathname": "/Users/jimburer/GitHub/cryptography/python_library/identity_and_access/identity/authenticator/authenticator_storage.py", "exc_info": "Traceback (most recent call last):\n  File \"/Users/jimburer/GitHub/cryptography/.venv/lib/python3.8/site-packages/django/db/backends/utils.py\", line 86, in _execute\n    return self.cursor.execute(sql, params)\n  File \"/Users/jimburer/GitHub/cryptography/.venv/lib/python3.8/site-packages/django/db/backends/sqlite3/base.py\", line 396, in execute\n    return Database.Cursor.execute(self, query, params)\nsqlite3.IntegrityError: NOT NULL constraint failed: app_authenticatorstorage.authenticator\n\nThe above exception was the direct cause of the following exception:\n\nTraceback (most recent call last):\n  File \"/Users/jimburer/GitHub/cryptography/python_library/identity_and_access/identity/authenticator/authenticator_storage.py\", line 14, in authenticator_storage_def\n    AuthenticatorStorage.objects.create(store_date=datetime.now(), authenticator=my_derived_secure_hash)\n  File \"/Users/jimburer/GitHub/cryptography/.venv/lib/python3.8/site-packages/django/db/models/manager.py\", line 82, in manager_method\n    return getattr(self.get_queryset(), name)(*args, **kwargs)\n  File \"/Users/jimburer/GitHub/cryptography/.venv/lib/python3.8/site-packages/django/db/models/query.py\", line 433, in create\n    obj.save(force_insert=True, using=self.db)\n  File \"/Users/jimburer/GitHub/cryptography/.venv/lib/python3.8/site-packages/django/db/models/base.py\", line 745, in save\n    self.save_base(using=using, force_insert=force_insert,\n  File \"/Users/jimburer/GitHub/cryptography/.venv/lib/python3.8/site-packages/django/db/models/base.py\", line 782, in save_base\n    updated = self._save_table(\n  File \"/Users/jimburer/GitHub/cryptography/.venv/lib/python3.8/site-packages/django/db/models/base.py\", line 887, in _save_table\n    results = self._do_insert(cls._base_manager, using, fields, returning_fields, raw)\n  File \"/Users/jimburer/GitHub/cryptography/.venv/lib/python3.8/site-packages/django/db/models/base.py\", line 924, in _do_insert\n    return manager._insert(\n  File \"/Users/jimburer/GitHub/cryptography/.venv/lib/python3.8/site-packages/django/db/models/manager.py\", line 82, in manager_method\n    return getattr(self.get_queryset(), name)(*args, **kwargs)\n  File \"/Users/jimburer/GitHub/cryptography/.venv/lib/python3.8/site-packages/django/db/models/query.py\", line 1204, in _insert\n    return query.get_compiler(using=using).execute_sql(returning_fields)\n  File \"/Users/jimburer/GitHub/cryptography/.venv/lib/python3.8/site-packages/django/db/models/sql/compiler.py\", line 1392, in execute_sql\n    cursor.execute(sql, params)\n  File \"/Users/jimburer/GitHub/cryptography/.venv/lib/python3.8/site-packages/django/db/backends/utils.py\", line 100, in execute\n    return super().execute(sql, params)\n  File \"/Users/jimburer/GitHub/cryptography/.venv/lib/python3.8/site-packages/django/db/backends/utils.py\", line 68, in execute\n    return self._execute_with_wrappers(sql, params, many=False, executor=self._execute)\n  File \"/Users/jimburer/GitHub/cryptography/.venv/lib/python3.8/site-packages/django/db/backends/utils.py\", line 77, in _execute_with_wrappers\n    return executor(sql, params, many, context)\n  File \"/Users/jimburer/GitHub/cryptography/.venv/lib/python3.8/site-packages/django/db/backends/utils.py\", line 86, in _execute\n    return self.cursor.execute(sql, params)\n  File \"/Users/jimburer/GitHub/cryptography/.venv/lib/python3.8/site-packages/django/db/utils.py\", line 90, in __exit__\n    raise dj_exc_value.with_traceback(traceback) from exc_value\n  File \"/Users/jimburer/GitHub/cryptography/.venv/lib/python3.8/site-packages/django/db/backends/utils.py\", line 86, in _execute\n    return self.cursor.execute(sql, params)\n  File \"/Users/jimburer/GitHub/cryptography/.venv/lib/python3.8/site-packages/django/db/backends/sqlite3/base.py\", line 396, in execute\n    return Database.Cursor.execute(self, query, params)\ndjango.db.utils.IntegrityError: NOT NULL constraint failed: app_authenticatorstorage.authenticator"}
{"message": "invalid literal for int() with base 10: b'E-772tvdgwEvbuYHtnwuzPo3ynDngW1YPWA7aqw4E7w='", "time": "2020-07-13T19:47:29.759029", "level": "DEBUG", "filename": "byte_conversion.py", "funcName": "byte_conversion_def", "module": "byte_conversion", "pathname": "/Users/jimburer/GitHub/cryptography/python_library/data/data_transformation/type_conversion/byte_conversion.py", "exc_info": "Traceback (most recent call last):\n  File \"/Users/jimburer/GitHub/cryptography/python_library/data/data_transformation/type_conversion/byte_conversion.py\", line 6, in byte_conversion_def\n    in_bytes_as_int = int(in_bytes)\nValueError: invalid literal for int() with base 10: b'E-772tvdgwEvbuYHtnwuzPo3ynDngW1YPWA7aqw4E7w='"}
{"message": "'bytes' object has no attribute 'encode'", "time": "2020-07-13T19:47:29.759311", "level": "DEBUG", "filename": "byte_conversion.py", "funcName": "byte_conversion_def", "module": "byte_conversion", "pathname": "/Users/jimburer/GitHub/cryptography/python_library/data/data_transformation/type_conversion/byte_conversion.py", "exc_info": "Traceback (most recent call last):\n  File \"/Users/jimburer/GitHub/cryptography/python_library/data/data_transformation/type_conversion/byte_conversion.py\", line 13, in byte_conversion_def\n    as_bytes = in_bytes.encode('utf-8')\nAttributeError: 'bytes' object has no attribute 'encode'"}
{"message": "data must be bytes", "time": "2020-07-13T19:47:29.759452", "level": "DEBUG", "filename": "encryption.py", "funcName": "encryption_def", "module": "encryption", "pathname": "/Users/jimburer/GitHub/cryptography/python_library/data/data_transformation/data_confidentiality/encryption/encryption.py", "exc_info": "Traceback (most recent call last):\n  File \"/Users/jimburer/GitHub/cryptography/python_library/data/data_transformation/data_confidentiality/encryption/encryption.py\", line 31, in encryption_def\n    ciphertext = encrypted_object.encrypt(data_as_bytes)\n  File \"/Users/jimburer/GitHub/cryptography/.venv/lib/python3.8/site-packages/cryptography/fernet.py\", line 52, in encrypt\n    return self._encrypt_from_parts(data, current_time, iv)\n  File \"/Users/jimburer/GitHub/cryptography/.venv/lib/python3.8/site-packages/cryptography/fernet.py\", line 55, in _encrypt_from_parts\n    utils._check_bytes(\"data\", data)\n  File \"/Users/jimburer/GitHub/cryptography/.venv/lib/python3.8/site-packages/cryptography/utils.py\", line 31, in _check_bytes\n    raise TypeError(\"{} must be bytes\".format(name))\nTypeError: data must be bytes"}
{"message": "invalid literal for int() with base 10: b'uHMt_yLvipO29blb6qSN2Hq_knPHl-ONQwUqcmOXvvU='", "time": "2020-07-13T19:49:45.070319", "level": "DEBUG", "filename": "byte_conversion.py", "funcName": "byte_conversion_def", "module": "byte_conversion", "pathname": "/Users/jimburer/GitHub/cryptography/python_library/data/data_transformation/type_conversion/byte_conversion.py", "exc_info": "Traceback (most recent call last):\n  File \"/Users/jimburer/GitHub/cryptography/python_library/data/data_transformation/type_conversion/byte_conversion.py\", line 6, in byte_conversion_def\n    in_bytes_as_int = int(in_bytes)\nValueError: invalid literal for int() with base 10: b'uHMt_yLvipO29blb6qSN2Hq_knPHl-ONQwUqcmOXvvU='"}
{"message": "'bytes' object has no attribute 'encode'", "time": "2020-07-13T19:49:45.070625", "level": "DEBUG", "filename": "byte_conversion.py", "funcName": "byte_conversion_def", "module": "byte_conversion", "pathname": "/Users/jimburer/GitHub/cryptography/python_library/data/data_transformation/type_conversion/byte_conversion.py", "exc_info": "Traceback (most recent call last):\n  File \"/Users/jimburer/GitHub/cryptography/python_library/data/data_transformation/type_conversion/byte_conversion.py\", line 13, in byte_conversion_def\n    as_bytes = in_bytes.encode('utf-8')\nAttributeError: 'bytes' object has no attribute 'encode'"}
{"message": "data must be bytes", "time": "2020-07-13T19:49:45.070814", "level": "DEBUG", "filename": "encryption.py", "funcName": "encryption_def", "module": "encryption", "pathname": "/Users/jimburer/GitHub/cryptography/python_library/data/data_transformation/data_confidentiality/encryption/encryption.py", "exc_info": "Traceback (most recent call last):\n  File \"/Users/jimburer/GitHub/cryptography/python_library/data/data_transformation/data_confidentiality/encryption/encryption.py\", line 31, in encryption_def\n    ciphertext = encrypted_object.encrypt(data_as_bytes)\n  File \"/Users/jimburer/GitHub/cryptography/.venv/lib/python3.8/site-packages/cryptography/fernet.py\", line 52, in encrypt\n    return self._encrypt_from_parts(data, current_time, iv)\n  File \"/Users/jimburer/GitHub/cryptography/.venv/lib/python3.8/site-packages/cryptography/fernet.py\", line 55, in _encrypt_from_parts\n    utils._check_bytes(\"data\", data)\n  File \"/Users/jimburer/GitHub/cryptography/.venv/lib/python3.8/site-packages/cryptography/utils.py\", line 31, in _check_bytes\n    raise TypeError(\"{} must be bytes\".format(name))\nTypeError: data must be bytes"}
{"message": "invalid literal for int() with base 10: b'lzoEoD9MfAyAGIjxfdegXaYUqN4WSTquXu5HiZGArGo='", "time": "2020-07-13T19:58:41.163853", "level": "DEBUG", "filename": "byte_conversion.py", "funcName": "byte_conversion_def", "module": "byte_conversion", "pathname": "/Users/jimburer/GitHub/cryptography/python_library/data/data_transformation/type_conversion/byte_conversion.py", "exc_info": "Traceback (most recent call last):\n  File \"/Users/jimburer/GitHub/cryptography/python_library/data/data_transformation/type_conversion/byte_conversion.py\", line 6, in byte_conversion_def\n    in_bytes_as_int = int(in_bytes)\nValueError: invalid literal for int() with base 10: b'lzoEoD9MfAyAGIjxfdegXaYUqN4WSTquXu5HiZGArGo='"}
{"message": "'bytes' object has no attribute 'encode'", "time": "2020-07-13T19:58:41.164543", "level": "DEBUG", "filename": "byte_conversion.py", "funcName": "byte_conversion_def", "module": "byte_conversion", "pathname": "/Users/jimburer/GitHub/cryptography/python_library/data/data_transformation/type_conversion/byte_conversion.py", "exc_info": "Traceback (most recent call last):\n  File \"/Users/jimburer/GitHub/cryptography/python_library/data/data_transformation/type_conversion/byte_conversion.py\", line 13, in byte_conversion_def\n    as_bytes = in_bytes.encode('utf-8')\nAttributeError: 'bytes' object has no attribute 'encode'"}
{"message": "data must be bytes", "time": "2020-07-13T19:58:41.164720", "level": "DEBUG", "filename": "encryption.py", "funcName": "encryption_def", "module": "encryption", "pathname": "/Users/jimburer/GitHub/cryptography/python_library/data/data_transformation/data_confidentiality/encryption/encryption.py", "exc_info": "Traceback (most recent call last):\n  File \"/Users/jimburer/GitHub/cryptography/python_library/data/data_transformation/data_confidentiality/encryption/encryption.py\", line 31, in encryption_def\n    ciphertext = encrypted_object.encrypt(data_as_bytes)\n  File \"/Users/jimburer/GitHub/cryptography/.venv/lib/python3.8/site-packages/cryptography/fernet.py\", line 52, in encrypt\n    return self._encrypt_from_parts(data, current_time, iv)\n  File \"/Users/jimburer/GitHub/cryptography/.venv/lib/python3.8/site-packages/cryptography/fernet.py\", line 55, in _encrypt_from_parts\n    utils._check_bytes(\"data\", data)\n  File \"/Users/jimburer/GitHub/cryptography/.venv/lib/python3.8/site-packages/cryptography/utils.py\", line 31, in _check_bytes\n    raise TypeError(\"{} must be bytes\".format(name))\nTypeError: data must be bytes"}
{"message": "invalid literal for int() with base 10: 'test'", "time": "2020-07-13T20:10:57.892810", "level": "DEBUG", "filename": "byte_conversion.py", "funcName": "byte_conversion_def", "module": "byte_conversion", "pathname": "/Users/jimburer/GitHub/cryptography/python_library/data/data_transformation/type_conversion/byte_conversion.py", "exc_info": "Traceback (most recent call last):\n  File \"/Users/jimburer/GitHub/cryptography/python_library/data/data_transformation/type_conversion/byte_conversion.py\", line 6, in byte_conversion_def\n    in_bytes_as_int = int(in_bytes)\nValueError: invalid literal for int() with base 10: 'test'"}
{"message": "invalid literal for int() with base 10: 'test'", "time": "2020-07-13T20:23:08.956290", "level": "DEBUG", "filename": "byte_conversion.py", "funcName": "byte_conversion_def", "module": "byte_conversion", "pathname": "/Users/jimburer/GitHub/cryptography/python_library/data/data_transformation/type_conversion/byte_conversion.py", "exc_info": "Traceback (most recent call last):\n  File \"/Users/jimburer/GitHub/cryptography/python_library/data/data_transformation/type_conversion/byte_conversion.py\", line 6, in byte_conversion_def\n    in_bytes_as_int = int(in_bytes)\nValueError: invalid literal for int() with base 10: 'test'"}
{"message": "invalid literal for int() with base 10: 'test'", "time": "2020-07-13T20:23:35.491654", "level": "DEBUG", "filename": "byte_conversion.py", "funcName": "byte_conversion_def", "module": "byte_conversion", "pathname": "/Users/jimburer/GitHub/cryptography/python_library/data/data_transformation/type_conversion/byte_conversion.py", "exc_info": "Traceback (most recent call last):\n  File \"/Users/jimburer/GitHub/cryptography/python_library/data/data_transformation/type_conversion/byte_conversion.py\", line 6, in byte_conversion_def\n    in_bytes_as_int = int(in_bytes)\nValueError: invalid literal for int() with base 10: 'test'"}
{"message": "invalid literal for int() with base 10: 'test'", "time": "2020-07-13T20:24:01.736731", "level": "DEBUG", "filename": "byte_conversion.py", "funcName": "byte_conversion_def", "module": "byte_conversion", "pathname": "/Users/jimburer/GitHub/cryptography/python_library/data/data_transformation/type_conversion/byte_conversion.py", "exc_info": "Traceback (most recent call last):\n  File \"/Users/jimburer/GitHub/cryptography/python_library/data/data_transformation/type_conversion/byte_conversion.py\", line 6, in byte_conversion_def\n    in_bytes_as_int = int(in_bytes)\nValueError: invalid literal for int() with base 10: 'test'"}
{"message": "invalid literal for int() with base 10: 'test'", "time": "2020-07-13T20:28:26.759129", "level": "DEBUG", "filename": "byte_conversion.py", "funcName": "byte_conversion_def", "module": "byte_conversion", "pathname": "/Users/jimburer/GitHub/cryptography/python_library/data/data_transformation/type_conversion/byte_conversion.py", "exc_info": "Traceback (most recent call last):\n  File \"/Users/jimburer/GitHub/cryptography/python_library/data/data_transformation/type_conversion/byte_conversion.py\", line 6, in byte_conversion_def\n    in_bytes_as_int = int(in_bytes)\nValueError: invalid literal for int() with base 10: 'test'"}
{"message": "invalid literal for int() with base 10: 'test'", "time": "2020-07-18T16:07:27.666651", "level": "DEBUG", "filename": "byte_conversion.py", "funcName": "byte_conversion_def", "module": "byte_conversion", "pathname": "/Users/jimburer/GitHub/cryptography/python_library/data/data_transformation/type_conversion/byte_conversion.py", "exc_info": "Traceback (most recent call last):\n  File \"/Users/jimburer/GitHub/cryptography/python_library/data/data_transformation/type_conversion/byte_conversion.py\", line 6, in byte_conversion_def\n    in_bytes_as_int = int(in_bytes)\nValueError: invalid literal for int() with base 10: 'test'"}
{"message": "format must be an item from the PublicFormat enum", "time": "2020-07-18T20:21:49.122687", "level": "DEBUG", "filename": "asymmetric_key_generation.py", "funcName": "asymmetric_key_generation_def", "module": "asymmetric_key_generation", "pathname": "/Users/jimburer/GitHub/cryptography/python_library/identity_and_access/identity/authenticator/key/asymmetric_key/asymmetric_key_generation.py", "exc_info": "Traceback (most recent call last):\n  File \"/Users/jimburer/GitHub/cryptography/python_library/identity_and_access/identity/authenticator/key/asymmetric_key/asymmetric_key_generation.py\", line 21, in asymmetric_key_generation_def\n    f.write(peer_asymmetric_public_key.public_bytes(encoding=serialization.Encoding.PEM, format=serialization.PrivateFormat.TraditionalOpenSSL))\n  File \"/Users/jimburer/GitHub/cryptography/.venv/lib/python3.8/site-packages/cryptography/hazmat/backends/openssl/rsa.py\", line 464, in public_bytes\n    return self._backend._public_key_bytes(\n  File \"/Users/jimburer/GitHub/cryptography/.venv/lib/python3.8/site-packages/cryptography/hazmat/backends/openssl/backend.py\", line 1911, in _public_key_bytes\n    raise TypeError(\nTypeError: format must be an item from the PublicFormat enum"}
{"message": "invalid literal for int() with base 10: 'test'", "time": "2020-07-24T13:45:42.134226", "level": "DEBUG", "filename": "byte_conversion.py", "funcName": "byte_conversion_def", "module": "byte_conversion", "pathname": "/Users/jimburer/GitHub/cryptography/python_library/data/data_transformation/type_conversion/byte_conversion.py", "exc_info": "Traceback (most recent call last):\n  File \"/Users/jimburer/GitHub/cryptography/python_library/data/data_transformation/type_conversion/byte_conversion.py\", line 6, in byte_conversion_def\n    in_bytes_as_int = int(in_bytes)\nValueError: invalid literal for int() with base 10: 'test'"}
{"message": "invalid literal for int() with base 10: 'test'", "time": "2020-07-24T13:54:11.127080", "level": "DEBUG", "filename": "byte_conversion.py", "funcName": "byte_conversion_def", "module": "byte_conversion", "pathname": "/Users/jimburer/GitHub/cryptography/python_library/data/data_transformation/type_conversion/byte_conversion.py", "exc_info": "Traceback (most recent call last):\n  File \"/Users/jimburer/GitHub/cryptography/python_library/data/data_transformation/type_conversion/byte_conversion.py\", line 6, in byte_conversion_def\n    in_bytes_as_int = int(in_bytes)\nValueError: invalid literal for int() with base 10: 'test'"}
{"message": "object of type '_DHPrivateKey' has no len()", "time": "2020-07-24T14:01:58.369079", "level": "DEBUG", "filename": "shared_key_generation.py", "funcName": "shared_key_generation_def", "module": "shared_key_generation", "pathname": "/Users/jimburer/GitHub/cryptography/python_library/identity_and_access/identity/authenticator/key/shared_key/shared_key_generation.py", "exc_info": "Traceback (most recent call last):\n  File \"/Users/jimburer/GitHub/cryptography/python_library/identity_and_access/identity/authenticator/key/shared_key/shared_key_generation.py\", line 22, in shared_key_generation_def\n    print(len(shared_private_key))\nTypeError: object of type '_DHPrivateKey' has no len()"}
{"message": "int() argument must be a string, a bytes-like object or a number, not 'NoneType'", "time": "2020-07-24T14:01:58.369477", "level": "DEBUG", "filename": "byte_conversion.py", "funcName": "byte_conversion_def", "module": "byte_conversion", "pathname": "/Users/jimburer/GitHub/cryptography/python_library/data/data_transformation/type_conversion/byte_conversion.py", "exc_info": "Traceback (most recent call last):\n  File \"/Users/jimburer/GitHub/cryptography/python_library/data/data_transformation/type_conversion/byte_conversion.py\", line 6, in byte_conversion_def\n    in_bytes_as_int = int(in_bytes)\nTypeError: int() argument must be a string, a bytes-like object or a number, not 'NoneType'"}
{"message": "'NoneType' object has no attribute 'encode'", "time": "2020-07-24T14:01:58.369826", "level": "DEBUG", "filename": "byte_conversion.py", "funcName": "byte_conversion_def", "module": "byte_conversion", "pathname": "/Users/jimburer/GitHub/cryptography/python_library/data/data_transformation/type_conversion/byte_conversion.py", "exc_info": "Traceback (most recent call last):\n  File \"/Users/jimburer/GitHub/cryptography/python_library/data/data_transformation/type_conversion/byte_conversion.py\", line 13, in byte_conversion_def\n    as_bytes = in_bytes.encode('utf-8')\nAttributeError: 'NoneType' object has no attribute 'encode'"}
{"message": "a bytes-like object is required, not 'NoneType'", "time": "2020-07-24T14:01:58.370002", "level": "DEBUG", "filename": "derived_secure_hash.py", "funcName": "derived_secure_hash_def", "module": "derived_secure_hash", "pathname": "/Users/jimburer/GitHub/cryptography/python_library/data/data_transformation/data_confidentiality/hash/secure_hash/derived_secure_hash/derived_secure_hash.py", "exc_info": "Traceback (most recent call last):\n  File \"/Users/jimburer/GitHub/cryptography/python_library/data/data_transformation/data_confidentiality/hash/secure_hash/derived_secure_hash/derived_secure_hash.py\", line 45, in derived_secure_hash_def\n    dk = hashlib.pbkdf2_hmac(secure_hash_algorithm_name, authenticator_as_bytes, random_number_as_bytes, iterations, derived_secure_hash_length)\nTypeError: a bytes-like object is required, not 'NoneType'"}
{"message": "NOT NULL constraint failed: app_authenticatorstorage.authenticator", "time": "2020-07-24T14:01:58.372394", "level": "DEBUG", "filename": "authenticator_storage.py", "funcName": "authenticator_storage_def", "module": "authenticator_storage", "pathname": "/Users/jimburer/GitHub/cryptography/python_library/identity_and_access/identity/authenticator/authenticator_storage.py", "exc_info": "Traceback (most recent call last):\n  File \"/Users/jimburer/GitHub/cryptography/.venv/lib/python3.8/site-packages/django/db/backends/utils.py\", line 86, in _execute\n    return self.cursor.execute(sql, params)\n  File \"/Users/jimburer/GitHub/cryptography/.venv/lib/python3.8/site-packages/django/db/backends/sqlite3/base.py\", line 396, in execute\n    return Database.Cursor.execute(self, query, params)\nsqlite3.IntegrityError: NOT NULL constraint failed: app_authenticatorstorage.authenticator\n\nThe above exception was the direct cause of the following exception:\n\nTraceback (most recent call last):\n  File \"/Users/jimburer/GitHub/cryptography/python_library/identity_and_access/identity/authenticator/authenticator_storage.py\", line 14, in authenticator_storage_def\n    AuthenticatorStorage.objects.create(store_date=datetime.now(), authenticator=my_derived_secure_hash)\n  File \"/Users/jimburer/GitHub/cryptography/.venv/lib/python3.8/site-packages/django/db/models/manager.py\", line 82, in manager_method\n    return getattr(self.get_queryset(), name)(*args, **kwargs)\n  File \"/Users/jimburer/GitHub/cryptography/.venv/lib/python3.8/site-packages/django/db/models/query.py\", line 433, in create\n    obj.save(force_insert=True, using=self.db)\n  File \"/Users/jimburer/GitHub/cryptography/.venv/lib/python3.8/site-packages/django/db/models/base.py\", line 745, in save\n    self.save_base(using=using, force_insert=force_insert,\n  File \"/Users/jimburer/GitHub/cryptography/.venv/lib/python3.8/site-packages/django/db/models/base.py\", line 782, in save_base\n    updated = self._save_table(\n  File \"/Users/jimburer/GitHub/cryptography/.venv/lib/python3.8/site-packages/django/db/models/base.py\", line 887, in _save_table\n    results = self._do_insert(cls._base_manager, using, fields, returning_fields, raw)\n  File \"/Users/jimburer/GitHub/cryptography/.venv/lib/python3.8/site-packages/django/db/models/base.py\", line 924, in _do_insert\n    return manager._insert(\n  File \"/Users/jimburer/GitHub/cryptography/.venv/lib/python3.8/site-packages/django/db/models/manager.py\", line 82, in manager_method\n    return getattr(self.get_queryset(), name)(*args, **kwargs)\n  File \"/Users/jimburer/GitHub/cryptography/.venv/lib/python3.8/site-packages/django/db/models/query.py\", line 1204, in _insert\n    return query.get_compiler(using=using).execute_sql(returning_fields)\n  File \"/Users/jimburer/GitHub/cryptography/.venv/lib/python3.8/site-packages/django/db/models/sql/compiler.py\", line 1392, in execute_sql\n    cursor.execute(sql, params)\n  File \"/Users/jimburer/GitHub/cryptography/.venv/lib/python3.8/site-packages/django/db/backends/utils.py\", line 100, in execute\n    return super().execute(sql, params)\n  File \"/Users/jimburer/GitHub/cryptography/.venv/lib/python3.8/site-packages/django/db/backends/utils.py\", line 68, in execute\n    return self._execute_with_wrappers(sql, params, many=False, executor=self._execute)\n  File \"/Users/jimburer/GitHub/cryptography/.venv/lib/python3.8/site-packages/django/db/backends/utils.py\", line 77, in _execute_with_wrappers\n    return executor(sql, params, many, context)\n  File \"/Users/jimburer/GitHub/cryptography/.venv/lib/python3.8/site-packages/django/db/backends/utils.py\", line 86, in _execute\n    return self.cursor.execute(sql, params)\n  File \"/Users/jimburer/GitHub/cryptography/.venv/lib/python3.8/site-packages/django/db/utils.py\", line 90, in __exit__\n    raise dj_exc_value.with_traceback(traceback) from exc_value\n  File \"/Users/jimburer/GitHub/cryptography/.venv/lib/python3.8/site-packages/django/db/backends/utils.py\", line 86, in _execute\n    return self.cursor.execute(sql, params)\n  File \"/Users/jimburer/GitHub/cryptography/.venv/lib/python3.8/site-packages/django/db/backends/sqlite3/base.py\", line 396, in execute\n    return Database.Cursor.execute(self, query, params)\ndjango.db.utils.IntegrityError: NOT NULL constraint failed: app_authenticatorstorage.authenticator"}
{"message": "invalid literal for int() with base 10: 'test'", "time": "2020-07-24T15:04:11.879119", "level": "DEBUG", "filename": "byte_conversion.py", "funcName": "byte_conversion_def", "module": "byte_conversion", "pathname": "/Users/jimburer/GitHub/cryptography/python_library/data/data_transformation/type_conversion/byte_conversion.py", "exc_info": "Traceback (most recent call last):\n  File \"/Users/jimburer/GitHub/cryptography/python_library/data/data_transformation/type_conversion/byte_conversion.py\", line 6, in byte_conversion_def\n    in_bytes_as_int = int(in_bytes)\nValueError: invalid literal for int() with base 10: 'test'"}
{"message": "int() argument must be a string, a bytes-like object or a number, not 'tuple'", "time": "2020-07-24T15:59:19.144006", "level": "DEBUG", "filename": "byte_conversion.py", "funcName": "byte_conversion_def", "module": "byte_conversion", "pathname": "/Users/jimburer/GitHub/cryptography/python_library/data/data_transformation/type_conversion/byte_conversion.py", "exc_info": "Traceback (most recent call last):\n  File \"/Users/jimburer/GitHub/cryptography/python_library/data/data_transformation/type_conversion/byte_conversion.py\", line 6, in byte_conversion_def\n    in_bytes_as_int = int(in_bytes)\nTypeError: int() argument must be a string, a bytes-like object or a number, not 'tuple'"}
{"message": "'tuple' object has no attribute 'encode'", "time": "2020-07-24T15:59:19.145135", "level": "DEBUG", "filename": "byte_conversion.py", "funcName": "byte_conversion_def", "module": "byte_conversion", "pathname": "/Users/jimburer/GitHub/cryptography/python_library/data/data_transformation/type_conversion/byte_conversion.py", "exc_info": "Traceback (most recent call last):\n  File \"/Users/jimburer/GitHub/cryptography/python_library/data/data_transformation/type_conversion/byte_conversion.py\", line 13, in byte_conversion_def\n    as_bytes = in_bytes.encode('utf-8')\nAttributeError: 'tuple' object has no attribute 'encode'"}
{"message": "a bytes-like object is required, not 'NoneType'", "time": "2020-07-24T15:59:19.145361", "level": "DEBUG", "filename": "derived_secure_hash.py", "funcName": "derived_secure_hash_def", "module": "derived_secure_hash", "pathname": "/Users/jimburer/GitHub/cryptography/python_library/data/data_transformation/data_confidentiality/hash/secure_hash/derived_secure_hash/derived_secure_hash.py", "exc_info": "Traceback (most recent call last):\n  File \"/Users/jimburer/GitHub/cryptography/python_library/data/data_transformation/data_confidentiality/hash/secure_hash/derived_secure_hash/derived_secure_hash.py\", line 45, in derived_secure_hash_def\n    dk = hashlib.pbkdf2_hmac(secure_hash_algorithm_name, authenticator_as_bytes, random_number_as_bytes, iterations, derived_secure_hash_length)\nTypeError: a bytes-like object is required, not 'NoneType'"}
{"message": "NOT NULL constraint failed: app_authenticatorstorage.authenticator", "time": "2020-07-24T15:59:19.149189", "level": "DEBUG", "filename": "authenticator_storage.py", "funcName": "authenticator_storage_def", "module": "authenticator_storage", "pathname": "/Users/jimburer/GitHub/cryptography/python_library/identity_and_access/identity/authenticator/authenticator_storage.py", "exc_info": "Traceback (most recent call last):\n  File \"/Users/jimburer/GitHub/cryptography/.venv/lib/python3.8/site-packages/django/db/backends/utils.py\", line 86, in _execute\n    return self.cursor.execute(sql, params)\n  File \"/Users/jimburer/GitHub/cryptography/.venv/lib/python3.8/site-packages/django/db/backends/sqlite3/base.py\", line 396, in execute\n    return Database.Cursor.execute(self, query, params)\nsqlite3.IntegrityError: NOT NULL constraint failed: app_authenticatorstorage.authenticator\n\nThe above exception was the direct cause of the following exception:\n\nTraceback (most recent call last):\n  File \"/Users/jimburer/GitHub/cryptography/python_library/identity_and_access/identity/authenticator/authenticator_storage.py\", line 14, in authenticator_storage_def\n    AuthenticatorStorage.objects.create(store_date=datetime.now(), authenticator=my_derived_secure_hash)\n  File \"/Users/jimburer/GitHub/cryptography/.venv/lib/python3.8/site-packages/django/db/models/manager.py\", line 82, in manager_method\n    return getattr(self.get_queryset(), name)(*args, **kwargs)\n  File \"/Users/jimburer/GitHub/cryptography/.venv/lib/python3.8/site-packages/django/db/models/query.py\", line 433, in create\n    obj.save(force_insert=True, using=self.db)\n  File \"/Users/jimburer/GitHub/cryptography/.venv/lib/python3.8/site-packages/django/db/models/base.py\", line 745, in save\n    self.save_base(using=using, force_insert=force_insert,\n  File \"/Users/jimburer/GitHub/cryptography/.venv/lib/python3.8/site-packages/django/db/models/base.py\", line 782, in save_base\n    updated = self._save_table(\n  File \"/Users/jimburer/GitHub/cryptography/.venv/lib/python3.8/site-packages/django/db/models/base.py\", line 887, in _save_table\n    results = self._do_insert(cls._base_manager, using, fields, returning_fields, raw)\n  File \"/Users/jimburer/GitHub/cryptography/.venv/lib/python3.8/site-packages/django/db/models/base.py\", line 924, in _do_insert\n    return manager._insert(\n  File \"/Users/jimburer/GitHub/cryptography/.venv/lib/python3.8/site-packages/django/db/models/manager.py\", line 82, in manager_method\n    return getattr(self.get_queryset(), name)(*args, **kwargs)\n  File \"/Users/jimburer/GitHub/cryptography/.venv/lib/python3.8/site-packages/django/db/models/query.py\", line 1204, in _insert\n    return query.get_compiler(using=using).execute_sql(returning_fields)\n  File \"/Users/jimburer/GitHub/cryptography/.venv/lib/python3.8/site-packages/django/db/models/sql/compiler.py\", line 1392, in execute_sql\n    cursor.execute(sql, params)\n  File \"/Users/jimburer/GitHub/cryptography/.venv/lib/python3.8/site-packages/django/db/backends/utils.py\", line 100, in execute\n    return super().execute(sql, params)\n  File \"/Users/jimburer/GitHub/cryptography/.venv/lib/python3.8/site-packages/django/db/backends/utils.py\", line 68, in execute\n    return self._execute_with_wrappers(sql, params, many=False, executor=self._execute)\n  File \"/Users/jimburer/GitHub/cryptography/.venv/lib/python3.8/site-packages/django/db/backends/utils.py\", line 77, in _execute_with_wrappers\n    return executor(sql, params, many, context)\n  File \"/Users/jimburer/GitHub/cryptography/.venv/lib/python3.8/site-packages/django/db/backends/utils.py\", line 86, in _execute\n    return self.cursor.execute(sql, params)\n  File \"/Users/jimburer/GitHub/cryptography/.venv/lib/python3.8/site-packages/django/db/utils.py\", line 90, in __exit__\n    raise dj_exc_value.with_traceback(traceback) from exc_value\n  File \"/Users/jimburer/GitHub/cryptography/.venv/lib/python3.8/site-packages/django/db/backends/utils.py\", line 86, in _execute\n    return self.cursor.execute(sql, params)\n  File \"/Users/jimburer/GitHub/cryptography/.venv/lib/python3.8/site-packages/django/db/backends/sqlite3/base.py\", line 396, in execute\n    return Database.Cursor.execute(self, query, params)\ndjango.db.utils.IntegrityError: NOT NULL constraint failed: app_authenticatorstorage.authenticator"}
{"message": "invalid literal for int() with base 10: 'test'", "time": "2020-07-24T18:12:19.405687", "level": "DEBUG", "filename": "byte_conversion.py", "funcName": "byte_conversion_def", "module": "byte_conversion", "pathname": "/Users/jimburer/GitHub/cryptography/python_library/data/data_transformation/type_conversion/byte_conversion.py", "exc_info": "Traceback (most recent call last):\n  File \"/Users/jimburer/GitHub/cryptography/python_library/data/data_transformation/type_conversion/byte_conversion.py\", line 6, in byte_conversion_def\n    in_bytes_as_int = int(in_bytes)\nValueError: invalid literal for int() with base 10: 'test'"}
{"message": "invalid literal for int() with base 10: 'test'", "time": "2020-07-24T18:50:01.815076", "level": "DEBUG", "filename": "byte_conversion.py", "funcName": "byte_conversion_def", "module": "byte_conversion", "pathname": "/Users/jimburer/GitHub/cryptography/python_library/data/data_transformation/type_conversion/byte_conversion.py", "exc_info": "Traceback (most recent call last):\n  File \"/Users/jimburer/GitHub/cryptography/python_library/data/data_transformation/type_conversion/byte_conversion.py\", line 6, in byte_conversion_def\n    in_bytes_as_int = int(in_bytes)\nValueError: invalid literal for int() with base 10: 'test'"}
{"message": "invalid literal for int() with base 10: 'test'", "time": "2020-07-29T23:55:24.744430", "level": "DEBUG", "filename": "byte_conversion.py", "funcName": "byte_conversion_def", "module": "byte_conversion", "pathname": "/Users/jimburer/GitHub/python/python_library/data/data_transformation/type_conversion/byte_conversion.py", "exc_info": "Traceback (most recent call last):\n  File \"/Users/jimburer/GitHub/python/python_library/data/data_transformation/type_conversion/byte_conversion.py\", line 6, in byte_conversion_def\n    in_bytes_as_int = int(in_bytes)\nValueError: invalid literal for int() with base 10: 'test'"}
{"message": "'secure_pseudorandom_number_byte_size'", "time": "2020-08-13T15:08:33.134596", "level": "DEBUG", "filename": "secure_pseudorandom_number.py", "funcName": "secure_pseudorandom_number_def", "module": "secure_pseudorandom_number", "pathname": "/Users/jimburer/GitHub/python/python_library/data/information/algorithm/random_number/pseudorandom_number/secure_pseudorandom_number.py", "exc_info": "Traceback (most recent call last):\n  File \"/Users/jimburer/GitHub/python/python_library/data/information/algorithm/random_number/pseudorandom_number/secure_pseudorandom_number.py\", line 14, in secure_pseudorandom_number_def\n    if policy_dict['secure_pseudorandom_number_byte_size']:\nKeyError: 'secure_pseudorandom_number_byte_size'"}
{"message": "'secure_pseudorandom_number_byte_size'", "time": "2020-08-13T15:08:53.240334", "level": "DEBUG", "filename": "secure_pseudorandom_number.py", "funcName": "secure_pseudorandom_number_def", "module": "secure_pseudorandom_number", "pathname": "/Users/jimburer/GitHub/python/python_library/data/information/algorithm/random_number/pseudorandom_number/secure_pseudorandom_number.py", "exc_info": "Traceback (most recent call last):\n  File \"/Users/jimburer/GitHub/python/python_library/data/information/algorithm/random_number/pseudorandom_number/secure_pseudorandom_number.py\", line 14, in secure_pseudorandom_number_def\n    if policy_dict['secure_pseudorandom_number_byte_size']:\nKeyError: 'secure_pseudorandom_number_byte_size'"}
{"message": "'secure_pseudorandom_number_byte_size'", "time": "2020-08-13T15:09:01.098532", "level": "DEBUG", "filename": "secure_pseudorandom_number.py", "funcName": "secure_pseudorandom_number_def", "module": "secure_pseudorandom_number", "pathname": "/Users/jimburer/GitHub/python/python_library/data/information/algorithm/random_number/pseudorandom_number/secure_pseudorandom_number.py", "exc_info": "Traceback (most recent call last):\n  File \"/Users/jimburer/GitHub/python/python_library/data/information/algorithm/random_number/pseudorandom_number/secure_pseudorandom_number.py\", line 14, in secure_pseudorandom_number_def\n    if policy_dict['secure_pseudorandom_number_byte_size']:\nKeyError: 'secure_pseudorandom_number_byte_size'"}
{"message": "a bytes-like object is required, not 'str'", "time": "2020-08-14T12:50:51.410313", "level": "DEBUG", "filename": "hash.py", "funcName": "hash_def", "module": "hash", "pathname": "/Users/jimburer/GitHub/python/python_library/data/data_transformation/data_confidentiality/hash/hash.py", "exc_info": "Traceback (most recent call last):\n  File \"/Users/jimburer/GitHub/python/python_library/data/data_transformation/data_confidentiality/hash/hash.py\", line 10, in hash_def\n    my_hash = zlib.adler32(data)\nTypeError: a bytes-like object is required, not 'str'"}
{"message": "a bytes-like object is required, not 'str'", "time": "2020-08-14T12:53:03.095582", "level": "DEBUG", "filename": "hash_alt.py", "funcName": "hash_alt_def", "module": "hash_alt", "pathname": "/Users/jimburer/GitHub/python/python_library/data/data_transformation/data_confidentiality/hash/hash_alt.py", "exc_info": "Traceback (most recent call last):\n  File \"/Users/jimburer/GitHub/python/python_library/data/data_transformation/data_confidentiality/hash/hash_alt.py\", line 10, in hash_alt_def\n    my_hash = zlib.adler32(data)\nTypeError: a bytes-like object is required, not 'str'"}
{"message": "a bytes-like object is required, not 'str'", "time": "2020-08-14T12:53:08.026559", "level": "DEBUG", "filename": "hash_alt.py", "funcName": "hash_alt_def", "module": "hash_alt", "pathname": "/Users/jimburer/GitHub/python/python_library/data/data_transformation/data_confidentiality/hash/hash_alt.py", "exc_info": "Traceback (most recent call last):\n  File \"/Users/jimburer/GitHub/python/python_library/data/data_transformation/data_confidentiality/hash/hash_alt.py\", line 10, in hash_alt_def\n    my_hash = zlib.adler32(data)\nTypeError: a bytes-like object is required, not 'str'"}
{"message": "'module' object is not callable", "time": "2020-08-14T12:55:09.118209", "level": "DEBUG", "filename": "hash_alt.py", "funcName": "hash_alt_def", "module": "hash_alt", "pathname": "/Users/jimburer/GitHub/python/python_library/data/data_transformation/data_confidentiality/hash/hash_alt.py", "exc_info": "Traceback (most recent call last):\n  File \"/Users/jimburer/GitHub/python/python_library/data/data_transformation/data_confidentiality/hash/hash_alt.py\", line 11, in hash_alt_def\n    data_as_bytes = byte_conversion(data)\nTypeError: 'module' object is not callable"}
{"message": "'module' object is not callable", "time": "2020-08-14T12:56:20.315917", "level": "DEBUG", "filename": "hash_alt.py", "funcName": "hash_alt_def", "module": "hash_alt", "pathname": "/Users/jimburer/GitHub/python/python_library/data/data_transformation/data_confidentiality/hash/hash_alt.py", "exc_info": "Traceback (most recent call last):\n  File \"/Users/jimburer/GitHub/python/python_library/data/data_transformation/data_confidentiality/hash/hash_alt.py\", line 11, in hash_alt_def\n    data_as_bytes = byte_conversion(data)\nTypeError: 'module' object is not callable"}
{"message": "invalid literal for int() with base 10: 'test'", "time": "2020-08-14T12:59:55.144286", "level": "DEBUG", "filename": "byte_conversion.py", "funcName": "byte_conversion_def", "module": "byte_conversion", "pathname": "/Users/jimburer/GitHub/python/python_library/data/data_transformation/type_conversion/byte_conversion.py", "exc_info": "Traceback (most recent call last):\n  File \"/Users/jimburer/GitHub/python/python_library/data/data_transformation/type_conversion/byte_conversion.py\", line 5, in byte_conversion_def\n    in_bytes_as_int = int(in_bytes)\nValueError: invalid literal for int() with base 10: 'test'"}
{"message": "invalid literal for int() with base 10: 'testing'", "time": "2020-08-14T13:01:31.068782", "level": "DEBUG", "filename": "byte_conversion.py", "funcName": "byte_conversion_def", "module": "byte_conversion", "pathname": "/Users/jimburer/GitHub/python/python_library/data/data_transformation/type_conversion/byte_conversion.py", "exc_info": "Traceback (most recent call last):\n  File \"/Users/jimburer/GitHub/python/python_library/data/data_transformation/type_conversion/byte_conversion.py\", line 5, in byte_conversion_def\n    in_bytes_as_int = int(in_bytes)\nValueError: invalid literal for int() with base 10: 'testing'"}
{"message": "invalid literal for int() with base 10: 'johnsonandjohnsoncity'", "time": "2020-08-14T13:01:43.660418", "level": "DEBUG", "filename": "byte_conversion.py", "funcName": "byte_conversion_def", "module": "byte_conversion", "pathname": "/Users/jimburer/GitHub/python/python_library/data/data_transformation/type_conversion/byte_conversion.py", "exc_info": "Traceback (most recent call last):\n  File \"/Users/jimburer/GitHub/python/python_library/data/data_transformation/type_conversion/byte_conversion.py\", line 5, in byte_conversion_def\n    in_bytes_as_int = int(in_bytes)\nValueError: invalid literal for int() with base 10: 'johnsonandjohnsoncity'"}
{"message": "invalid literal for int() with base 10: 'test'", "time": "2020-08-14T13:03:34.971219", "level": "DEBUG", "filename": "byte_conversion.py", "funcName": "byte_conversion_def", "module": "byte_conversion", "pathname": "/Users/jimburer/GitHub/python/python_library/data/data_transformation/type_conversion/byte_conversion.py", "exc_info": "Traceback (most recent call last):\n  File \"/Users/jimburer/GitHub/python/python_library/data/data_transformation/type_conversion/byte_conversion.py\", line 5, in byte_conversion_def\n    in_bytes_as_int = int(in_bytes)\nValueError: invalid literal for int() with base 10: 'test'"}
{"message": "invalid literal for int() with base 10: 'test'", "time": "2020-08-14T13:06:57.810251", "level": "DEBUG", "filename": "byte_conversion.py", "funcName": "byte_conversion_def", "module": "byte_conversion", "pathname": "/Users/jimburer/GitHub/python/python_library/data/data_transformation/type_conversion/byte_conversion.py", "exc_info": "Traceback (most recent call last):\n  File \"/Users/jimburer/GitHub/python/python_library/data/data_transformation/type_conversion/byte_conversion.py\", line 5, in byte_conversion_def\n    in_bytes_as_int = int(in_bytes)\nValueError: invalid literal for int() with base 10: 'test'"}
{"message": "Unicode-objects must be encoded before hashing", "time": "2020-08-14T14:55:44.871036", "level": "DEBUG", "filename": "secure_hash.py", "funcName": "secure_hash_def", "module": "secure_hash", "pathname": "/Users/jimburer/GitHub/python/python_library/data/data_transformation/data_confidentiality/hash/secure_hash.py", "exc_info": "Traceback (most recent call last):\n  File \"/Users/jimburer/GitHub/python/python_library/data/data_transformation/data_confidentiality/hash/secure_hash.py\", line 12, in secure_hash_def\n    secure_hash.update(data)\nTypeError: Unicode-objects must be encoded before hashing"}
{"message": "Unicode-objects must be encoded before hashing", "time": "2020-08-14T15:02:01.992201", "level": "DEBUG", "filename": "secure_hash.py", "funcName": "secure_hash_def", "module": "secure_hash", "pathname": "/Users/jimburer/GitHub/python/python_library/data/data_transformation/data_confidentiality/hash/secure_hash.py", "exc_info": "Traceback (most recent call last):\n  File \"/Users/jimburer/GitHub/python/python_library/data/data_transformation/data_confidentiality/hash/secure_hash.py\", line 12, in secure_hash_def\n    secure_hash.update(data)\nTypeError: Unicode-objects must be encoded before hashing"}
{"message": "invalid literal for int() with base 10: 'test'", "time": "2020-08-14T15:03:07.052743", "level": "DEBUG", "filename": "byte_conversion.py", "funcName": "byte_conversion_def", "module": "byte_conversion", "pathname": "/Users/jimburer/GitHub/python/python_library/data/data_transformation/type_conversion/byte_conversion.py", "exc_info": "Traceback (most recent call last):\n  File \"/Users/jimburer/GitHub/python/python_library/data/data_transformation/type_conversion/byte_conversion.py\", line 5, in byte_conversion_def\n    in_bytes_as_int = int(in_bytes)\nValueError: invalid literal for int() with base 10: 'test'"}
{"message": "invalid literal for int() with base 10: 'test'", "time": "2020-08-14T15:04:05.298997", "level": "DEBUG", "filename": "byte_conversion.py", "funcName": "byte_conversion_def", "module": "byte_conversion", "pathname": "/Users/jimburer/GitHub/python/python_library/data/data_transformation/type_conversion/byte_conversion.py", "exc_info": "Traceback (most recent call last):\n  File \"/Users/jimburer/GitHub/python/python_library/data/data_transformation/type_conversion/byte_conversion.py\", line 5, in byte_conversion_def\n    in_bytes_as_int = int(in_bytes)\nValueError: invalid literal for int() with base 10: 'test'"}
{"message": "invalid literal for int() with base 10: 'test'", "time": "2020-08-14T15:04:37.968210", "level": "DEBUG", "filename": "byte_conversion.py", "funcName": "byte_conversion_def", "module": "byte_conversion", "pathname": "/Users/jimburer/GitHub/python/python_library/data/data_transformation/type_conversion/byte_conversion.py", "exc_info": "Traceback (most recent call last):\n  File \"/Users/jimburer/GitHub/python/python_library/data/data_transformation/type_conversion/byte_conversion.py\", line 5, in byte_conversion_def\n    in_bytes_as_int = int(in_bytes)\nValueError: invalid literal for int() with base 10: 'test'"}
{"message": "invalid literal for int() with base 10: 'test'", "time": "2020-08-14T15:07:42.217441", "level": "DEBUG", "filename": "byte_conversion.py", "funcName": "byte_conversion_def", "module": "byte_conversion", "pathname": "/Users/jimburer/GitHub/python/python_library/data/data_transformation/type_conversion/byte_conversion.py", "exc_info": "Traceback (most recent call last):\n  File \"/Users/jimburer/GitHub/python/python_library/data/data_transformation/type_conversion/byte_conversion.py\", line 5, in byte_conversion_def\n    in_bytes_as_int = int(in_bytes)\nValueError: invalid literal for int() with base 10: 'test'"}
{"message": "invalid literal for int() with base 10: 'test'", "time": "2020-08-14T15:11:14.424921", "level": "DEBUG", "filename": "byte_conversion.py", "funcName": "byte_conversion_def", "module": "byte_conversion", "pathname": "/Users/jimburer/GitHub/python/python_library/data/data_transformation/type_conversion/byte_conversion.py", "exc_info": "Traceback (most recent call last):\n  File \"/Users/jimburer/GitHub/python/python_library/data/data_transformation/type_conversion/byte_conversion.py\", line 5, in byte_conversion_def\n    in_bytes_as_int = int(in_bytes)\nValueError: invalid literal for int() with base 10: 'test'"}
{"message": "digest() takes exactly one argument (0 given)", "time": "2020-08-14T15:11:14.425242", "level": "DEBUG", "filename": "secure_hash.py", "funcName": "secure_hash_def", "module": "secure_hash", "pathname": "/Users/jimburer/GitHub/python/python_library/data/data_transformation/data_confidentiality/hash/secure_hash.py", "exc_info": "Traceback (most recent call last):\n  File \"/Users/jimburer/GitHub/python/python_library/data/data_transformation/data_confidentiality/hash/secure_hash.py\", line 15, in secure_hash_def\n    return secure_hash.digest(), secure_hash.name, secure_hash.hexdigest()\nTypeError: digest() takes exactly one argument (0 given)"}
{"message": "invalid literal for int() with base 10: 'test'", "time": "2020-08-14T15:12:03.398035", "level": "DEBUG", "filename": "byte_conversion.py", "funcName": "byte_conversion_def", "module": "byte_conversion", "pathname": "/Users/jimburer/GitHub/python/python_library/data/data_transformation/type_conversion/byte_conversion.py", "exc_info": "Traceback (most recent call last):\n  File \"/Users/jimburer/GitHub/python/python_library/data/data_transformation/type_conversion/byte_conversion.py\", line 5, in byte_conversion_def\n    in_bytes_as_int = int(in_bytes)\nValueError: invalid literal for int() with base 10: 'test'"}
{"message": "invalid literal for int() with base 10: 'test'", "time": "2020-08-14T15:13:22.768070", "level": "DEBUG", "filename": "byte_conversion.py", "funcName": "byte_conversion_def", "module": "byte_conversion", "pathname": "/Users/jimburer/GitHub/python/python_library/data/data_transformation/type_conversion/byte_conversion.py", "exc_info": "Traceback (most recent call last):\n  File \"/Users/jimburer/GitHub/python/python_library/data/data_transformation/type_conversion/byte_conversion.py\", line 5, in byte_conversion_def\n    in_bytes_as_int = int(in_bytes)\nValueError: invalid literal for int() with base 10: 'test'"}
{"message": "invalid literal for int() with base 10: 'test'", "time": "2020-08-14T15:13:49.460020", "level": "DEBUG", "filename": "byte_conversion.py", "funcName": "byte_conversion_def", "module": "byte_conversion", "pathname": "/Users/jimburer/GitHub/python/python_library/data/data_transformation/type_conversion/byte_conversion.py", "exc_info": "Traceback (most recent call last):\n  File \"/Users/jimburer/GitHub/python/python_library/data/data_transformation/type_conversion/byte_conversion.py\", line 5, in byte_conversion_def\n    in_bytes_as_int = int(in_bytes)\nValueError: invalid literal for int() with base 10: 'test'"}
{"message": "invalid literal for int() with base 10: 'test'", "time": "2020-08-14T15:38:54.679911", "level": "DEBUG", "filename": "byte_conversion.py", "funcName": "byte_conversion_def", "module": "byte_conversion", "pathname": "/Users/jimburer/GitHub/python/python_library/data/data_transformation/type_conversion/byte_conversion.py", "exc_info": "Traceback (most recent call last):\n  File \"/Users/jimburer/GitHub/python/python_library/data/data_transformation/type_conversion/byte_conversion.py\", line 5, in byte_conversion_def\n    in_bytes_as_int = int(in_bytes)\nValueError: invalid literal for int() with base 10: 'test'"}
{"message": "invalid literal for int() with base 10: 'test'", "time": "2020-08-20T15:39:48.872723", "level": "DEBUG", "filename": "byte_conversion.py", "funcName": "byte_conversion_def", "module": "byte_conversion", "pathname": "/Users/jimburer/GitHub/python/python_library/data/data_transformation/type_conversion/byte_conversion.py", "exc_info": "Traceback (most recent call last):\n  File \"/Users/jimburer/GitHub/python/python_library/data/data_transformation/type_conversion/byte_conversion.py\", line 5, in byte_conversion_def\n    in_bytes_as_int = int(in_bytes)\nValueError: invalid literal for int() with base 10: 'test'"}
{"message": "invalid literal for int() with base 10: 'test'", "time": "2020-08-20T15:43:43.216177", "level": "DEBUG", "filename": "byte_conversion.py", "funcName": "byte_conversion_def", "module": "byte_conversion", "pathname": "/Users/jimburer/GitHub/python/python_library/data/data_transformation/type_conversion/byte_conversion.py", "exc_info": "Traceback (most recent call last):\n  File \"/Users/jimburer/GitHub/python/python_library/data/data_transformation/type_conversion/byte_conversion.py\", line 5, in byte_conversion_def\n    in_bytes_as_int = int(in_bytes)\nValueError: invalid literal for int() with base 10: 'test'"}
{"message": "invalid literal for int() with base 10: 'test'", "time": "2020-08-20T15:43:43.216874", "level": "DEBUG", "filename": "byte_conversion.py", "funcName": "byte_conversion_def", "module": "byte_conversion", "pathname": "/Users/jimburer/GitHub/python/python_library/data/data_transformation/type_conversion/byte_conversion.py", "exc_info": "Traceback (most recent call last):\n  File \"/Users/jimburer/GitHub/python/python_library/data/data_transformation/type_conversion/byte_conversion.py\", line 5, in byte_conversion_def\n    in_bytes_as_int = int(in_bytes)\nValueError: invalid literal for int() with base 10: 'test'"}
